Workbook
Name 色號: 烤漆色號編碼!$A$2:$A$29
Name 烤漆粉號: 烤漆色號編碼!$A$2:$E$29

Sheet 庫存查詢表
A1: 庫存查詢表
B13: 選擇粉烤色號： | C13: K-91097G
B14: 粉烤代號： | C14: =IFERROR(VLOOKUP(C13,烤漆色號編碼!$A:$C,2,FALSE),"-") -> BKS1
B15: 廠商： | C15: =IFERROR(VLOOKUP(C13,烤漆色號編碼!$A:$E,5,FALSE),"-") -> 國麗
B17: 當前庫存： | C17: =IFERROR(VLOOKUP(C13,當前庫存!$C:$I,5,FALSE),"-") -> 17 | D17: 箱
B18: 散粉： | C18: =IFERROR(VLOOKUP(C13,當前庫存!$C:$I,4,FALSE),"-") -> 3 | D18: KG
B19: 總數量： | C19: =IFERROR(VLOOKUP(C13,烤漆色號編碼!$A:$D,4,FALSE)*C17+C18,"-"+D34) -> 428 | D19: KG | E19: ＜＜＜庫存
B21: 本月出庫總數量： | C21: =SUMIF(每日用粉紀錄表!C:C, C13, 每日用粉紀錄表!J:J) -> 297 | D21: KG
B23: 本月廢粉總數量
B24: 總數量： | C24: =IFERROR(VLOOKUP(B23,廢粉紀錄!B4:E4,3,FALSE),"-") -> 600 | D24: KG
B26: 本月用粉數量
B27: 總數量： | C27: =SUM(每日用粉紀錄表!J:J) -> 2188 | D27: KG

Sheet 每日用量查詢
B1: 用量查詢
B4: 查詢日期 | C4: 45957
B6: 色號 | C6: 代號 | D6: 用量 | E6: 庫存
B7: {=IFERROR(INDEX(每日用粉紀錄表!$C$3:$C$103, SMALL(IF($C$4=每日用粉紀錄表!$B$3:$B$103, ROW(每日用粉紀錄表!$B$3:$B$103)-ROW(每日用粉紀錄表!$B$3)+1), ROW(1:1))),"")} -> 008/2H056 | C7: {=IFERROR(INDEX(每日用粉紀錄表!$D$3:$D$103, SMALL(IF($C$4=每日用粉紀錄表!$B$3:$B$103, ROW(每日用粉紀錄表!$B$3:$B$103)-ROW(每日用粉紀錄表!$B$3)+1), ROW(1:1))),"")} -> YW1 | D7: {=IFERROR(INDEX(每日用粉紀錄表!$J$3:$J$103, SMALL(IF($C$4=每日用粉紀錄表!$B$3:$B$103, ROW(每日用粉紀錄表!$B$3:$B$103)-ROW(每日用粉紀錄表!$B$3)+1), ROW(1:1))),"")} -> 30 | E7: {=IFERROR(INDEX(每日用粉紀錄表!$E$3:$E$103, SMALL(IF($C$4=每日用粉紀錄表!$B$3:$B$103, ROW(每日用粉紀錄表!$B$3:$B$103)-ROW(每日用粉紀錄表!$B$3)+1), ROW(1:1))),"")} -> 12
B8: {=IFERROR(INDEX(每日用粉紀錄表!$C$3:$C$103, SMALL(IF($C$4=每日用粉紀錄表!$B$3:$B$103, ROW(每日用粉紀錄表!$B$3:$B$103)-ROW(每日用粉紀錄表!$B$3)+1), ROW(2:2))),"")} -> K-91097G | C8: {=IFERROR(INDEX(每日用粉紀錄表!$D$3:$D$103, SMALL(IF($C$4=每日用粉紀錄表!$B$3:$B$103, ROW(每日用粉紀錄表!$B$3:$B$103)-ROW(每日用粉紀錄表!$B$3)+1), ROW(2:2))),"")} -> BKS1 | D8: {=IFERROR(INDEX(每日用粉紀錄表!$J$3:$J$103, SMALL(IF($C$4=每日用粉紀錄表!$B$3:$B$103, ROW(每日用粉紀錄表!$B$3:$B$103)-ROW(每日用粉紀錄表!$B$3)+1), ROW(2:2))),"")} -> 16 | E8: {=IFERROR(INDEX(每日用粉紀錄表!$E$3:$E$103, SMALL(IF($C$4=每日用粉紀錄表!$B$3:$B$103, ROW(每日用粉紀錄表!$B$3:$B$103)-ROW(每日用粉紀錄表!$B$3)+1), ROW(2:2))),"")} -> 17
B9: {=IFERROR(INDEX(每日用粉紀錄表!$C$3:$C$103, SMALL(IF($C$4=每日用粉紀錄表!$B$3:$B$103, ROW(每日用粉紀錄表!$B$3:$B$103)-ROW(每日用粉紀錄表!$B$3)+1), ROW(3:3))),"")} -> 4605-505 | C9: {=IFERROR(INDEX(每日用粉紀錄表!$D$3:$D$103, SMALL(IF($C$4=每日用粉紀錄表!$B$3:$B$103, ROW(每日用粉紀錄表!$B$3:$B$103)-ROW(每日用粉紀錄表!$B$3)+1), ROW(3:3))),"")} -> EBK | D9: {=IFERROR(INDEX(每日用粉紀錄表!$J$3:$J$103, SMALL(IF($C$4=每日用粉紀錄表!$B$3:$B$103, ROW(每日用粉紀錄表!$B$3:$B$103)-ROW(每日用粉紀錄表!$B$3)+1), ROW(3:3))),"")} -> 0 | E9: {=IFERROR(INDEX(每日用粉紀錄表!$E$3:$E$103, SMALL(IF($C$4=每日用粉紀錄表!$B$3:$B$103, ROW(每日用粉紀錄表!$B$3:$B$103)-ROW(每日用粉紀錄表!$B$3)+1), ROW(3:3))),"")} -> 3
B10: {=IFERROR(INDEX(每日用粉紀錄表!$C$3:$C$103, SMALL(IF($C$4=每日用粉紀錄表!$B$3:$B$103, ROW(每日用粉紀錄表!$B$3:$B$103)-ROW(每日用粉紀錄表!$B$3)+1), ROW(4:4))),"")} -> 008/1H174 | C10: {=IFERROR(INDEX(每日用粉紀錄表!$D$3:$D$103, SMALL(IF($C$4=每日用粉紀錄表!$B$3:$B$103, ROW(每日用粉紀錄表!$B$3:$B$103)-ROW(每日用粉紀錄表!$B$3)+1), ROW(4:4))),"")} -> WE2 | D10: {=IFERROR(INDEX(每日用粉紀錄表!$J$3:$J$103, SMALL(IF($C$4=每日用粉紀錄表!$B$3:$B$103, ROW(每日用粉紀錄表!$B$3:$B$103)-ROW(每日用粉紀錄表!$B$3)+1), ROW(4:4))),"")} -> 84 | E10: {=IFERROR(INDEX(每日用粉紀錄表!$E$3:$E$103, SMALL(IF($C$4=每日用粉紀錄表!$B$3:$B$103, ROW(每日用粉紀錄表!$B$3:$B$103)-ROW(每日用粉紀錄表!$B$3)+1), ROW(4:4))),"")} -> 26
B11: {=IFERROR(INDEX(每日用粉紀錄表!$C$3:$C$103, SMALL(IF($C$4=每日用粉紀錄表!$B$3:$B$103, ROW(每日用粉紀錄表!$B$3:$B$103)-ROW(每日用粉紀錄表!$B$3)+1), ROW(5:5))),"")} -> 廢粉 | C11: {=IFERROR(INDEX(每日用粉紀錄表!$D$3:$D$103, SMALL(IF($C$4=每日用粉紀錄表!$B$3:$B$103, ROW(每日用粉紀錄表!$B$3:$B$103)-ROW(每日用粉紀錄表!$B$3)+1), ROW(5:5))),"")} -> - | D11: {=IFERROR(INDEX(每日用粉紀錄表!$J$3:$J$103, SMALL(IF($C$4=每日用粉紀錄表!$B$3:$B$103, ROW(每日用粉紀錄表!$B$3:$B$103)-ROW(每日用粉紀錄表!$B$3)+1), ROW(5:5))),"")} -> 25 | E11: {=IFERROR(INDEX(每日用粉紀錄表!$E$3:$E$103, SMALL(IF($C$4=每日用粉紀錄表!$B$3:$B$103, ROW(每日用粉紀錄表!$B$3:$B$103)-ROW(每日用粉紀錄表!$B$3)+1), ROW(5:5))),"")} -> -
B12: {=IFERROR(INDEX(每日用粉紀錄表!$C$3:$C$103, SMALL(IF($C$4=每日用粉紀錄表!$B$3:$B$103, ROW(每日用粉紀錄表!$B$3:$B$103)-ROW(每日用粉紀錄表!$B$3)+1), ROW(6:6))),"")} | C12: {=IFERROR(INDEX(每日用粉紀錄表!$D$3:$D$103, SMALL(IF($C$4=每日用粉紀錄表!$B$3:$B$103, ROW(每日用粉紀錄表!$B$3:$B$103)-ROW(每日用粉紀錄表!$B$3)+1), ROW(6:6))),"")} | D12: {=IFERROR(INDEX(每日用粉紀錄表!$J$3:$J$103, SMALL(IF($C$4=每日用粉紀錄表!$B$3:$B$103, ROW(每日用粉紀錄表!$B$3:$B$103)-ROW(每日用粉紀錄表!$B$3)+1), ROW(6:6))),"")} | E12: {=IFERROR(INDEX(每日用粉紀錄表!$E$3:$E$103, SMALL(IF($C$4=每日用粉紀錄表!$B$3:$B$103, ROW(每日用粉紀錄表!$B$3:$B$103)-ROW(每日用粉紀錄表!$B$3)+1), ROW(6:6))),"")}
B13: {=IFERROR(INDEX(每日用粉紀錄表!$C$3:$C$103, SMALL(IF($C$4=每日用粉紀錄表!$B$3:$B$103, ROW(每日用粉紀錄表!$B$3:$B$103)-ROW(每日用粉紀錄表!$B$3)+1), ROW(7:7))),"")} | C13: {=IFERROR(INDEX(每日用粉紀錄表!$D$3:$D$103, SMALL(IF($C$4=每日用粉紀錄表!$B$3:$B$103, ROW(每日用粉紀錄表!$B$3:$B$103)-ROW(每日用粉紀錄表!$B$3)+1), ROW(7:7))),"")} | D13: {=IFERROR(INDEX(每日用粉紀錄表!$J$3:$J$103, SMALL(IF($C$4=每日用粉紀錄表!$B$3:$B$103, ROW(每日用粉紀錄表!$B$3:$B$103)-ROW(每日用粉紀錄表!$B$3)+1), ROW(7:7))),"")} | E13: {=IFERROR(INDEX(每日用粉紀錄表!$E$3:$E$103, SMALL(IF($C$4=每日用粉紀錄表!$B$3:$B$103, ROW(每日用粉紀錄表!$B$3:$B$103)-ROW(每日用粉紀錄表!$B$3)+1), ROW(7:7))),"")}
B14: {=IFERROR(INDEX(每日用粉紀錄表!$C$3:$C$103, SMALL(IF($C$4=每日用粉紀錄表!$B$3:$B$103, ROW(每日用粉紀錄表!$B$3:$B$103)-ROW(每日用粉紀錄表!$B$3)+1), ROW(8:8))),"")} | C14: {=IFERROR(INDEX(每日用粉紀錄表!$D$3:$D$103, SMALL(IF($C$4=每日用粉紀錄表!$B$3:$B$103, ROW(每日用粉紀錄表!$B$3:$B$103)-ROW(每日用粉紀錄表!$B$3)+1), ROW(8:8))),"")} | D14: {=IFERROR(INDEX(每日用粉紀錄表!$J$3:$J$103, SMALL(IF($C$4=每日用粉紀錄表!$B$3:$B$103, ROW(每日用粉紀錄表!$B$3:$B$103)-ROW(每日用粉紀錄表!$B$3)+1), ROW(8:8))),"")} | E14: {=IFERROR(INDEX(每日用粉紀錄表!$E$3:$E$103, SMALL(IF($C$4=每日用粉紀錄表!$B$3:$B$103, ROW(每日用粉紀錄表!$B$3:$B$103)-ROW(每日用粉紀錄表!$B$3)+1), ROW(8:8))),"")}
B15: {=IFERROR(INDEX(每日用粉紀錄表!$C$3:$C$103, SMALL(IF($C$4=每日用粉紀錄表!$B$3:$B$103, ROW(每日用粉紀錄表!$B$3:$B$103)-ROW(每日用粉紀錄表!$B$3)+1), ROW(9:9))),"")} | C15: {=IFERROR(INDEX(每日用粉紀錄表!$D$3:$D$103, SMALL(IF($C$4=每日用粉紀錄表!$B$3:$B$103, ROW(每日用粉紀錄表!$B$3:$B$103)-ROW(每日用粉紀錄表!$B$3)+1), ROW(9:9))),"")} | D15: {=IFERROR(INDEX(每日用粉紀錄表!$J$3:$J$103, SMALL(IF($C$4=每日用粉紀錄表!$B$3:$B$103, ROW(每日用粉紀錄表!$B$3:$B$103)-ROW(每日用粉紀錄表!$B$3)+1), ROW(9:9))),"")} | E15: {=IFERROR(INDEX(每日用粉紀錄表!$J$3:$J$103, SMALL(IF($C$4=每日用粉紀錄表!$B$3:$B$103, ROW(每日用粉紀錄表!$B$3:$B$103)-ROW(每日用粉紀錄表!$B$3)+1), ROW(9:9))),"")}
B16: {=IFERROR(INDEX(每日用粉紀錄表!$C$3:$C$103, SMALL(IF($C$4=每日用粉紀錄表!$B$3:$B$103, ROW(每日用粉紀錄表!$B$3:$B$103)-ROW(每日用粉紀錄表!$B$3)+1), ROW(10:10))),"")} | C16: {=IFERROR(INDEX(每日用粉紀錄表!$D$3:$D$103, SMALL(IF($C$4=每日用粉紀錄表!$B$3:$B$103, ROW(每日用粉紀錄表!$B$3:$B$103)-ROW(每日用粉紀錄表!$B$3)+1), ROW(10:10))),"")} | D16: {=IFERROR(INDEX(每日用粉紀錄表!$J$3:$J$103, SMALL(IF($C$4=每日用粉紀錄表!$B$3:$B$103, ROW(每日用粉紀錄表!$B$3:$B$103)-ROW(每日用粉紀錄表!$B$3)+1), ROW(10:10))),"")} | E16: {=IFERROR(INDEX(每日用粉紀錄表!$J$3:$J$103, SMALL(IF($C$4=每日用粉紀錄表!$B$3:$B$103, ROW(每日用粉紀錄表!$B$3:$B$103)-ROW(每日用粉紀錄表!$B$3)+1), ROW(10:10))),"")}
B17: {=IFERROR(INDEX(每日用粉紀錄表!$C$3:$C$103, SMALL(IF($C$4=每日用粉紀錄表!$B$3:$B$103, ROW(每日用粉紀錄表!$B$3:$B$103)-ROW(每日用粉紀錄表!$B$3)+1), ROW(11:11))),"")} | C17: {=IFERROR(INDEX(每日用粉紀錄表!$D$3:$D$103, SMALL(IF($C$4=每日用粉紀錄表!$B$3:$B$103, ROW(每日用粉紀錄表!$B$3:$B$103)-ROW(每日用粉紀錄表!$B$3)+1), ROW(11:11))),"")} | D17: {=IFERROR(INDEX(每日用粉紀錄表!$J$3:$J$103, SMALL(IF($C$4=每日用粉紀錄表!$B$3:$B$103, ROW(每日用粉紀錄表!$B$3:$B$103)-ROW(每日用粉紀錄表!$B$3)+1), ROW(11:11))),"")} | E17: {=IFERROR(INDEX(每日用粉紀錄表!$J$3:$J$103, SMALL(IF($C$4=每日用粉紀錄表!$B$3:$B$103, ROW(每日用粉紀錄表!$B$3:$B$103)-ROW(每日用粉紀錄表!$B$3)+1), ROW(11:11))),"")}
B18: {=IFERROR(INDEX(每日用粉紀錄表!$C$3:$C$103, SMALL(IF($C$4=每日用粉紀錄表!$B$3:$B$103, ROW(每日用粉紀錄表!$B$3:$B$103)-ROW(每日用粉紀錄表!$B$3)+1), ROW(12:12))),"")} | C18: {=IFERROR(INDEX(每日用粉紀錄表!$D$3:$D$103, SMALL(IF($C$4=每日用粉紀錄表!$B$3:$B$103, ROW(每日用粉紀錄表!$B$3:$B$103)-ROW(每日用粉紀錄表!$B$3)+1), ROW(12:12))),"")} | D18: {=IFERROR(INDEX(每日用粉紀錄表!$J$3:$J$103, SMALL(IF($C$4=每日用粉紀錄表!$B$3:$B$103, ROW(每日用粉紀錄表!$B$3:$B$103)-ROW(每日用粉紀錄表!$B$3)+1), ROW(12:12))),"")} | E18: {=IFERROR(INDEX(每日用粉紀錄表!$J$3:$J$103, SMALL(IF($C$4=每日用粉紀錄表!$B$3:$B$103, ROW(每日用粉紀錄表!$B$3:$B$103)-ROW(每日用粉紀錄表!$B$3)+1), ROW(12:12))),"")}
B19: {=IFERROR(INDEX(每日用粉紀錄表!$C$3:$C$103, SMALL(IF($C$4=每日用粉紀錄表!$B$3:$B$103, ROW(每日用粉紀錄表!$B$3:$B$103)-ROW(每日用粉紀錄表!$B$3)+1), ROW(13:13))),"")} | C19: {=IFERROR(INDEX(每日用粉紀錄表!$D$3:$D$103, SMALL(IF($C$4=每日用粉紀錄表!$B$3:$B$103, ROW(每日用粉紀錄表!$B$3:$B$103)-ROW(每日用粉紀錄表!$B$3)+1), ROW(13:13))),"")} | D19: {=IFERROR(INDEX(每日用粉紀錄表!$J$3:$J$103, SMALL(IF($C$4=每日用粉紀錄表!$B$3:$B$103, ROW(每日用粉紀錄表!$B$3:$B$103)-ROW(每日用粉紀錄表!$B$3)+1), ROW(13:13))),"")} | E19: {=IFERROR(INDEX(每日用粉紀錄表!$J$3:$J$103, SMALL(IF($C$4=每日用粉紀錄表!$B$3:$B$103, ROW(每日用粉紀錄表!$B$3:$B$103)-ROW(每日用粉紀錄表!$B$3)+1), ROW(13:13))),"")}
B20: {=IFERROR(INDEX(每日用粉紀錄表!$C$3:$C$103, SMALL(IF($C$4=每日用粉紀錄表!$B$3:$B$103, ROW(每日用粉紀錄表!$B$3:$B$103)-ROW(每日用粉紀錄表!$B$3)+1), ROW(14:14))),"")} | C20: {=IFERROR(INDEX(每日用粉紀錄表!$D$3:$D$103, SMALL(IF($C$4=每日用粉紀錄表!$B$3:$B$103, ROW(每日用粉紀錄表!$B$3:$B$103)-ROW(每日用粉紀錄表!$B$3)+1), ROW(14:14))),"")} | D20: {=IFERROR(INDEX(每日用粉紀錄表!$J$3:$J$103, SMALL(IF($C$4=每日用粉紀錄表!$B$3:$B$103, ROW(每日用粉紀錄表!$B$3:$B$103)-ROW(每日用粉紀錄表!$B$3)+1), ROW(14:14))),"")} | E20: {=IFERROR(INDEX(每日用粉紀錄表!$J$3:$J$103, SMALL(IF($C$4=每日用粉紀錄表!$B$3:$B$103, ROW(每日用粉紀錄表!$B$3:$B$103)-ROW(每日用粉紀錄表!$B$3)+1), ROW(14:14))),"")}
B21: {=IFERROR(INDEX(每日用粉紀錄表!$C$3:$C$103, SMALL(IF($C$4=每日用粉紀錄表!$B$3:$B$103, ROW(每日用粉紀錄表!$B$3:$B$103)-ROW(每日用粉紀錄表!$B$3)+1), ROW(15:15))),"")} | C21: {=IFERROR(INDEX(每日用粉紀錄表!$D$3:$D$103, SMALL(IF($C$4=每日用粉紀錄表!$B$3:$B$103, ROW(每日用粉紀錄表!$B$3:$B$103)-ROW(每日用粉紀錄表!$B$3)+1), ROW(15:15))),"")} | D21: {=IFERROR(INDEX(每日用粉紀錄表!$J$3:$J$103, SMALL(IF($C$4=每日用粉紀錄表!$B$3:$B$103, ROW(每日用粉紀錄表!$B$3:$B$103)-ROW(每日用粉紀錄表!$B$3)+1), ROW(15:15))),"")} | E21: {=IFERROR(INDEX(每日用粉紀錄表!$J$3:$J$103, SMALL(IF($C$4=每日用粉紀錄表!$B$3:$B$103, ROW(每日用粉紀錄表!$B$3:$B$103)-ROW(每日用粉紀錄表!$B$3)+1), ROW(15:15))),"")}
B22: {=IFERROR(INDEX(每日用粉紀錄表!$C$3:$C$103, SMALL(IF($C$4=每日用粉紀錄表!$B$3:$B$103, ROW(每日用粉紀錄表!$B$3:$B$103)-ROW(每日用粉紀錄表!$B$3)+1), ROW(16:16))),"")} | C22: {=IFERROR(INDEX(每日用粉紀錄表!$D$3:$D$103, SMALL(IF($C$4=每日用粉紀錄表!$B$3:$B$103, ROW(每日用粉紀錄表!$B$3:$B$103)-ROW(每日用粉紀錄表!$B$3)+1), ROW(16:16))),"")} | D22: {=IFERROR(INDEX(每日用粉紀錄表!$J$3:$J$103, SMALL(IF($C$4=每日用粉紀錄表!$B$3:$B$103, ROW(每日用粉紀錄表!$B$3:$B$103)-ROW(每日用粉紀錄表!$B$3)+1), ROW(16:16))),"")} | E22: {=IFERROR(INDEX(每日用粉紀錄表!$J$3:$J$103, SMALL(IF($C$4=每日用粉紀錄表!$B$3:$B$103, ROW(每日用粉紀錄表!$B$3:$B$103)-ROW(每日用粉紀錄表!$B$3)+1), ROW(16:16))),"")}
B23: {=IFERROR(INDEX(每日用粉紀錄表!$C$3:$C$103, SMALL(IF($C$4=每日用粉紀錄表!$B$3:$B$103, ROW(每日用粉紀錄表!$B$3:$B$103)-ROW(每日用粉紀錄表!$B$3)+1), ROW(17:17))),"")} | C23: {=IFERROR(INDEX(每日用粉紀錄表!$D$3:$D$103, SMALL(IF($C$4=每日用粉紀錄表!$B$3:$B$103, ROW(每日用粉紀錄表!$B$3:$B$103)-ROW(每日用粉紀錄表!$B$3)+1), ROW(17:17))),"")} | D23: {=IFERROR(INDEX(每日用粉紀錄表!$J$3:$J$103, SMALL(IF($C$4=每日用粉紀錄表!$B$3:$B$103, ROW(每日用粉紀錄表!$B$3:$B$103)-ROW(每日用粉紀錄表!$B$3)+1), ROW(17:17))),"")} | E23: {=IFERROR(INDEX(每日用粉紀錄表!$J$3:$J$103, SMALL(IF($C$4=每日用粉紀錄表!$B$3:$B$103, ROW(每日用粉紀錄表!$B$3:$B$103)-ROW(每日用粉紀錄表!$B$3)+1), ROW(17:17))),"")}
B24: {=IFERROR(INDEX(每日用粉紀錄表!$C$3:$C$103, SMALL(IF($C$4=每日用粉紀錄表!$B$3:$B$103, ROW(每日用粉紀錄表!$B$3:$B$103)-ROW(每日用粉紀錄表!$B$3)+1), ROW(18:18))),"")} | C24: {=IFERROR(INDEX(每日用粉紀錄表!$D$3:$D$103, SMALL(IF($C$4=每日用粉紀錄表!$B$3:$B$103, ROW(每日用粉紀錄表!$B$3:$B$103)-ROW(每日用粉紀錄表!$B$3)+1), ROW(18:18))),"")} | D24: {=IFERROR(INDEX(每日用粉紀錄表!$J$3:$J$103, SMALL(IF($C$4=每日用粉紀錄表!$B$3:$B$103, ROW(每日用粉紀錄表!$B$3:$B$103)-ROW(每日用粉紀錄表!$B$3)+1), ROW(18:18))),"")} | E24: {=IFERROR(INDEX(每日用粉紀錄表!$J$3:$J$103, SMALL(IF($C$4=每日用粉紀錄表!$B$3:$B$103, ROW(每日用粉紀錄表!$B$3:$B$103)-ROW(每日用粉紀錄表!$B$3)+1), ROW(18:18))),"")}
B25: {=IFERROR(INDEX(每日用粉紀錄表!$C$3:$C$103, SMALL(IF($C$4=每日用粉紀錄表!$B$3:$B$103, ROW(每日用粉紀錄表!$B$3:$B$103)-ROW(每日用粉紀錄表!$B$3)+1), ROW(19:19))),"")} | C25: {=IFERROR(INDEX(每日用粉紀錄表!$D$3:$D$103, SMALL(IF($C$4=每日用粉紀錄表!$B$3:$B$103, ROW(每日用粉紀錄表!$B$3:$B$103)-ROW(每日用粉紀錄表!$B$3)+1), ROW(19:19))),"")} | D25: {=IFERROR(INDEX(每日用粉紀錄表!$J$3:$J$103, SMALL(IF($C$4=每日用粉紀錄表!$B$3:$B$103, ROW(每日用粉紀錄表!$B$3:$B$103)-ROW(每日用粉紀錄表!$B$3)+1), ROW(19:19))),"")} | E25: {=IFERROR(INDEX(每日用粉紀錄表!$J$3:$J$103, SMALL(IF($C$4=每日用粉紀錄表!$B$3:$B$103, ROW(每日用粉紀錄表!$B$3:$B$103)-ROW(每日用粉紀錄表!$B$3)+1), ROW(19:19))),"")}
B26: {=IFERROR(INDEX(每日用粉紀錄表!$C$3:$C$103, SMALL(IF($C$4=每日用粉紀錄表!$B$3:$B$103, ROW(每日用粉紀錄表!$B$3:$B$103)-ROW(每日用粉紀錄表!$B$3)+1), ROW(20:20))),"")} | C26: {=IFERROR(INDEX(每日用粉紀錄表!$D$3:$D$103, SMALL(IF($C$4=每日用粉紀錄表!$B$3:$B$103, ROW(每日用粉紀錄表!$B$3:$B$103)-ROW(每日用粉紀錄表!$B$3)+1), ROW(20:20))),"")} | D26: {=IFERROR(INDEX(每日用粉紀錄表!$J$3:$J$103, SMALL(IF($C$4=每日用粉紀錄表!$B$3:$B$103, ROW(每日用粉紀錄表!$B$3:$B$103)-ROW(每日用粉紀錄表!$B$3)+1), ROW(20:20))),"")} | E26: {=IFERROR(INDEX(每日用粉紀錄表!$J$3:$J$103, SMALL(IF($C$4=每日用粉紀錄表!$B$3:$B$103, ROW(每日用粉紀錄表!$B$3:$B$103)-ROW(每日用粉紀錄表!$B$3)+1), ROW(20:20))),"")}
B27: {=IFERROR(INDEX(每日用粉紀錄表!$C$3:$C$103, SMALL(IF($C$4=每日用粉紀錄表!$B$3:$B$103, ROW(每日用粉紀錄表!$B$3:$B$103)-ROW(每日用粉紀錄表!$B$3)+1), ROW(21:21))),"")} | C27: {=IFERROR(INDEX(每日用粉紀錄表!$D$3:$D$103, SMALL(IF($C$4=每日用粉紀錄表!$B$3:$B$103, ROW(每日用粉紀錄表!$B$3:$B$103)-ROW(每日用粉紀錄表!$B$3)+1), ROW(21:21))),"")} | D27: {=IFERROR(INDEX(每日用粉紀錄表!$J$3:$J$103, SMALL(IF($C$4=每日用粉紀錄表!$B$3:$B$103, ROW(每日用粉紀錄表!$B$3:$B$103)-ROW(每日用粉紀錄表!$B$3)+1), ROW(21:21))),"")} | E27: {=IFERROR(INDEX(每日用粉紀錄表!$J$3:$J$103, SMALL(IF($C$4=每日用粉紀錄表!$B$3:$B$103, ROW(每日用粉紀錄表!$B$3:$B$103)-ROW(每日用粉紀錄表!$B$3)+1), ROW(21:21))),"")}
B28: {=IFERROR(INDEX(每日用粉紀錄表!$C$3:$C$103, SMALL(IF($C$4=每日用粉紀錄表!$B$3:$B$103, ROW(每日用粉紀錄表!$B$3:$B$103)-ROW(每日用粉紀錄表!$B$3)+1), ROW(22:22))),"")} | C28: {=IFERROR(INDEX(每日用粉紀錄表!$D$3:$D$103, SMALL(IF($C$4=每日用粉紀錄表!$B$3:$B$103, ROW(每日用粉紀錄表!$B$3:$B$103)-ROW(每日用粉紀錄表!$B$3)+1), ROW(22:22))),"")} | D28: {=IFERROR(INDEX(每日用粉紀錄表!$J$3:$J$103, SMALL(IF($C$4=每日用粉紀錄表!$B$3:$B$103, ROW(每日用粉紀錄表!$B$3:$B$103)-ROW(每日用粉紀錄表!$B$3)+1), ROW(22:22))),"")} | E28: {=IFERROR(INDEX(每日用粉紀錄表!$J$3:$J$103, SMALL(IF($C$4=每日用粉紀錄表!$B$3:$B$103, ROW(每日用粉紀錄表!$B$3:$B$103)-ROW(每日用粉紀錄表!$B$3)+1), ROW(22:22))),"")}
B29: {=IFERROR(INDEX(每日用粉紀錄表!$C$3:$C$103, SMALL(IF($C$4=每日用粉紀錄表!$B$3:$B$103, ROW(每日用粉紀錄表!$B$3:$B$103)-ROW(每日用粉紀錄表!$B$3)+1), ROW(23:23))),"")} | C29: {=IFERROR(INDEX(每日用粉紀錄表!$D$3:$D$103, SMALL(IF($C$4=每日用粉紀錄表!$B$3:$B$103, ROW(每日用粉紀錄表!$B$3:$B$103)-ROW(每日用粉紀錄表!$B$3)+1), ROW(23:23))),"")} | D29: {=IFERROR(INDEX(每日用粉紀錄表!$J$3:$J$103, SMALL(IF($C$4=每日用粉紀錄表!$B$3:$B$103, ROW(每日用粉紀錄表!$B$3:$B$103)-ROW(每日用粉紀錄表!$B$3)+1), ROW(23:23))),"")} | E29: {=IFERROR(INDEX(每日用粉紀錄表!$J$3:$J$103, SMALL(IF($C$4=每日用粉紀錄表!$B$3:$B$103, ROW(每日用粉紀錄表!$B$3:$B$103)-ROW(每日用粉紀錄表!$B$3)+1), ROW(23:23))),"")}
B30: {=IFERROR(INDEX(每日用粉紀錄表!$C$3:$C$103, SMALL(IF($C$4=每日用粉紀錄表!$B$3:$B$103, ROW(每日用粉紀錄表!$B$3:$B$103)-ROW(每日用粉紀錄表!$B$3)+1), ROW(24:24))),"")} | C30: {=IFERROR(INDEX(每日用粉紀錄表!$D$3:$D$103, SMALL(IF($C$4=每日用粉紀錄表!$B$3:$B$103, ROW(每日用粉紀錄表!$B$3:$B$103)-ROW(每日用粉紀錄表!$B$3)+1), ROW(24:24))),"")} | D30: {=IFERROR(INDEX(每日用粉紀錄表!$J$3:$J$103, SMALL(IF($C$4=每日用粉紀錄表!$B$3:$B$103, ROW(每日用粉紀錄表!$B$3:$B$103)-ROW(每日用粉紀錄表!$B$3)+1), ROW(24:24))),"")} | E30: {=IFERROR(INDEX(每日用粉紀錄表!$J$3:$J$103, SMALL(IF($C$4=每日用粉紀錄表!$B$3:$B$103, ROW(每日用粉紀錄表!$B$3:$B$103)-ROW(每日用粉紀錄表!$B$3)+1), ROW(24:24))),"")}
B31: {=IFERROR(INDEX(每日用粉紀錄表!$C$3:$C$103, SMALL(IF($C$4=每日用粉紀錄表!$B$3:$B$103, ROW(每日用粉紀錄表!$B$3:$B$103)-ROW(每日用粉紀錄表!$B$3)+1), ROW(25:25))),"")} | C31: {=IFERROR(INDEX(每日用粉紀錄表!$D$3:$D$103, SMALL(IF($C$4=每日用粉紀錄表!$B$3:$B$103, ROW(每日用粉紀錄表!$B$3:$B$103)-ROW(每日用粉紀錄表!$B$3)+1), ROW(25:25))),"")} | D31: {=IFERROR(INDEX(每日用粉紀錄表!$J$3:$J$103, SMALL(IF($C$4=每日用粉紀錄表!$B$3:$B$103, ROW(每日用粉紀錄表!$B$3:$B$103)-ROW(每日用粉紀錄表!$B$3)+1), ROW(25:25))),"")} | E31: {=IFERROR(INDEX(每日用粉紀錄表!$J$3:$J$103, SMALL(IF($C$4=每日用粉紀錄表!$B$3:$B$103, ROW(每日用粉紀錄表!$B$3:$B$103)-ROW(每日用粉紀錄表!$B$3)+1), ROW(25:25))),"")}
B32: {=IFERROR(INDEX(每日用粉紀錄表!$C$3:$C$103, SMALL(IF($C$4=每日用粉紀錄表!$B$3:$B$103, ROW(每日用粉紀錄表!$B$3:$B$103)-ROW(每日用粉紀錄表!$B$3)+1), ROW(26:26))),"")} | C32: {=IFERROR(INDEX(每日用粉紀錄表!$D$3:$D$103, SMALL(IF($C$4=每日用粉紀錄表!$B$3:$B$103, ROW(每日用粉紀錄表!$B$3:$B$103)-ROW(每日用粉紀錄表!$B$3)+1), ROW(26:26))),"")} | D32: {=IFERROR(INDEX(每日用粉紀錄表!$J$3:$J$103, SMALL(IF($C$4=每日用粉紀錄表!$B$3:$B$103, ROW(每日用粉紀錄表!$B$3:$B$103)-ROW(每日用粉紀錄表!$B$3)+1), ROW(26:26))),"")} | E32: {=IFERROR(INDEX(每日用粉紀錄表!$J$3:$J$103, SMALL(IF($C$4=每日用粉紀錄表!$B$3:$B$103, ROW(每日用粉紀錄表!$B$3:$B$103)-ROW(每日用粉紀錄表!$B$3)+1), ROW(26:26))),"")}
B33: {=IFERROR(INDEX(每日用粉紀錄表!$C$3:$C$103, SMALL(IF($C$4=每日用粉紀錄表!$B$3:$B$103, ROW(每日用粉紀錄表!$B$3:$B$103)-ROW(每日用粉紀錄表!$B$3)+1), ROW(27:27))),"")} | C33: {=IFERROR(INDEX(每日用粉紀錄表!$D$3:$D$103, SMALL(IF($C$4=每日用粉紀錄表!$B$3:$B$103, ROW(每日用粉紀錄表!$B$3:$B$103)-ROW(每日用粉紀錄表!$B$3)+1), ROW(27:27))),"")}

Sheet 歷年使用粉號
A1: 烤漆廠 | B1: 粉色 | C1: 代號 | D1: 使用狀況 | E1: 粉號 | F1: 粉廠 | G1: 屬性 | H1: 機種 | J1: 慶宇未標有粉
A2: x | B2: 白色 | C2: WE | E2: MS-A-07146(MRP) | F2: X
A3: 慶宇/德瑞昌 | B3: 白色 | C3: WE | E3: EC053T | F3: 致宗行 | G3: 室內(調合粉)
B4: 白色 | C4: WE | E4: DP-11485 | F4: 國麗 | G4: 高耐侯 | H4: 遊戲機
A5: x | B5: 白色 | C5: WE1 | E5: MS-EA010T (MRP) | F5: 高頻
A6: 慶宇 | B6: 白色 | C6: WE1 | E6: MS-A-09152 | F6: 台粉 | G6: 室外(耐黃變) | J6: V (已不做了)
A7: 德瑞昌 | B7: 白色 | C7: WE1 | E7: DP-1856 | F7: 國麗 | G7: 高耐侯 | H7: 136、166 | I7: 有做過QV
A8: x | B8: 白色 | C8: WE2 | E8: MS-PA-1437Y | F8: X | H8: 136禮品機
A9: x | B9: 白色 | C9: WE3 | E9: MS-PA-156Y (MRP) | F9: X | H9: 40023
A10: 慶宇 | B10: 白色 | C10: WE3 | E10: MS-LT-102051P | F10: 台粉 | G10: 室外 | H10: 游戲機 | J10: V(X)
A11: 新祥興 | B11: 耐候白 | C11: WE4 | E11: MS-2267AT | F11: 華邦 | G11: 高耐侯 | H11: 393SO
A12: x | B12: 米白 | C12: RWE | E12: MS-780-2409 | F12: X
A13: x | B13: 米錘紋 | C13: WEH | E13: MS-H2-9419 | F13: X
A14: x | B14: 玫瑰白 | C14: WER | E14: MS-780-1B20 | F14: X
A15: 德瑞昌 | B15: 黃亮光 | C15: YW | E15: MS-EE024T | F15: 致宗行 | G15: 室內(調合粉) | H15: 娃娃機.一公三母.
A16: 大茗 | B16: 黃錘紋 | C16: YWH | E16: MS-790-41540H | F16: 國邦 | G16: 室內 | H16: 632籃球機.地鼠機.娃娃機 | I16: 台粉 AT-12148 室內
A17: 大茗 | B17: 黃錘紋 | C17: YWH | E17: AT-12148 | F17: 台粉 | G17: 室內 | H17: 632籃球機.地鼠機.娃娃機
A18: x | B18: 指定黃 | C18: YWP | E18: MS-EE217T | F18: X
A19: x | B19: 鵝黃色 | C19: GYW | E19: MS-JF-053 (MRP) | F19: X | H19: 800 (編德瑞昌廠內色號)
A20: 德瑞昌 | B20: 鵝黃色 | C20: GYW | E20: 4900-246 | F20: 台粉 | G20: 室外 | H20: 德瑞昌本來就有用
A21: 德瑞昌 | B21: 銀色 | C21: AT | E21: MS-780-49740S | F21: 國邦 | G21: 室外
A22: x | B22: 銀白色 | C22: ATW | E22: MS-780-49364ATS | F22: 國邦 | G22: 室外
A23: 大茗 | B23: 銀灰 | C23: ATG | E23: MS-780-9B65 | F23: 國邦 | G23: 室外 | H23: 637籃球機/遮片 | I23: 國邦 780-9Q70 室外
A24: x | B24: 銀灰 | C24: GYS | E24: MS-H2-8460 | F24: 高頻 | G24: 室內 | H24: 136
A25: x | B25: 深灰 | E25: MS-HA-2662 | F25: 高頻 | G25: 室內
A26: 德瑞昌 | B26: 馬卡龍藍 | C26: MBE | E26: MS-HE-7172Y | F26: 高頻 | G26: 室外
A27: 同華 | B27: 冷灰 | C27: CG | E27: MS-4400/742A | F27: 台粉 | G27: 室內 | H27: C218尊伯 | I27: 沈總確認不需改為室外粉
A28: 大茗/同華 | B28: 鐵灰 | C28: IG | E28: MS-EL217T | F28: 致宗行 | G28: 室內(調合粉) | H28: 籃球機(需改外粉)
A29: 德瑞昌 | B29: 鐵灰砂 | C29: IGS | E29: MS-EL365T | F29: 致宗行 | G29: 室內(調合粉) | H29: 兌幣機(需改外粉)
A30: x | B30: 灰砂紋 | E30: MS-H2-9293 | F30: X
A31: x | B31: 黑平光 | C31: BK | E31: MS-770-5200F2 (MRP) | F31: 國邦 | G31: 室內
A32: 德瑞昌 | B32: 黑平光 | C32: BK | E32: 4950-502 | F32: 台粉 | G32: 室外 | H32: 德瑞昌本來就有用
A33: x | B33: 黑砂 | C33: BKS | E33: MS-T3-9825S (MRP) | F33: 高頻 | G33: 室外
A34: 德瑞昌 | B34: 黑砂 | C34: BKS | E34: P3R90249 | F34: 高頻 | G34: 室外
A35: 大茗 | B35: 黑砂 | C35: BKS | E35: 780-45510H | F35: 國邦 | G35: 室外 | H35: 637籃球機
A36: x | B36: 新黑砂 | C36: BKS1 | E36: 780-45111H (MPR) | F36: 國邦 | G36: 室外
A37: 慶宇/德瑞昌 | B37: 新黑砂 | C37: BKS1 | E37: MS-K-9898G-2 | F37: 國麗 | G37: 調和混合粉 | H37: 333/328 | I37: 沒做過QV測試
A38: 德瑞昌 | B38: 亮黑 | C38: BKL | E38: MS-4900/501 | F38: 台粉 | G38: 室外 | H38: 德瑞昌本來就有用
A39: 慶宇/德瑞昌 | B39: 黑錘紋 | C39: BKH | E39: MS-EN402T | F39: 致宗行 | G39: 室內(調合粉)
A40: x | B40: 小花黑綿綿漆 | C40: BKC | E40: MS-5A24 | F40: X
...

Sheet 每日用粉紀錄表
B2: 日期 | C2: 粉號 | D2: 代號 | E2: 庫存 | F2: 出 | G2: 散粉 | H2: 重量(Kg) | I2: 回庫 | J2: 用量 | K2: 時段 | L2: 烤漆日期 | M2: 回收/不回收 | N2: 備註 | O2: 欄1
B3: 45926 | C3: 無烤漆 | D3: =IFERROR(VLOOKUP($C3,烤漆色號編碼!$A:$C,2,FALSE),"-") -> - | E3: =IFERROR(VLOOKUP($C3,當前庫存!$C:$I,5,FALSE),"-") -> - | H3: =IFERROR(VLOOKUP($C3,烤漆色號編碼!$A:$D,4,FALSE)*表格2[[#This Row],[出]]+表格2[[#This Row],[散粉]],"-") -> - | J3: =IFERROR(表格2[[#This Row],[重量(Kg)]]-表格2[[#This Row],[回庫]],"-") -> -
B4: 45927 | C4: 例假日 | D4: =IFERROR(VLOOKUP($C4,烤漆色號編碼!$A:$C,2,FALSE),"-") -> - | E4: =IFERROR(VLOOKUP($C4,當前庫存!$C:$I,5,FALSE),"-") -> - | H4: =IFERROR(VLOOKUP($C4,烤漆色號編碼!$A:$D,4,FALSE)*表格2[[#This Row],[出]]+表格2[[#This Row],[散粉]],"-") -> - | J4: =IFERROR(表格2[[#This Row],[重量(Kg)]]-表格2[[#This Row],[回庫]],"-") -> -
B5: 45928 | C5: 例假日 | D5: =IFERROR(VLOOKUP($C5,烤漆色號編碼!$A:$C,2,FALSE),"-") -> - | E5: =IFERROR(VLOOKUP($C5,當前庫存!$C:$I,5,FALSE),"-") -> - | H5: =IFERROR(VLOOKUP($C5,烤漆色號編碼!$A:$D,4,FALSE)*表格2[[#This Row],[出]]+表格2[[#This Row],[散粉]],"-") -> - | J5: =IFERROR(表格2[[#This Row],[重量(Kg)]]-表格2[[#This Row],[回庫]],"-") -> -
B6: 45929 | C6: 國定假日 | D6: =IFERROR(VLOOKUP($C6,烤漆色號編碼!$A:$C,2,FALSE),"-") -> - | E6: =IFERROR(VLOOKUP($C6,當前庫存!$C:$I,5,FALSE),"-") -> - | H6: =IFERROR(VLOOKUP($C6,烤漆色號編碼!$A:$D,4,FALSE)*表格2[[#This Row],[出]]+表格2[[#This Row],[散粉]],"-") -> - | J6: =IFERROR(表格2[[#This Row],[重量(Kg)]]-表格2[[#This Row],[回庫]],"-") -> -
B7: 45930 | C7: 4950-502 | D7: =IFERROR(VLOOKUP($C7,烤漆色號編碼!$A:$C,2,FALSE),"-") -> BK | E7: =IFERROR(VLOOKUP($C7,當前庫存!$C:$I,5,FALSE),"-") -> 4 | G7: 16 | H7: =IFERROR(VLOOKUP($C7,烤漆色號編碼!$A:$D,4,FALSE)*表格2[[#This Row],[出]]+表格2[[#This Row],[散粉]],"-") -> 16 | I7: 5 | J7: =IFERROR(表格2[[#This Row],[重量(Kg)]]-表格2[[#This Row],[回庫]],"-") -> 11
B8: 45930 | C8: 4605-505 | D8: =IFERROR(VLOOKUP($C8,烤漆色號編碼!$A:$C,2,FALSE),"-") -> EBK | E8: =IFERROR(VLOOKUP($C8,當前庫存!$C:$I,5,FALSE),"-") -> 3 | G8: 12 | H8: =IFERROR(VLOOKUP($C8,烤漆色號編碼!$A:$D,4,FALSE)*表格2[[#This Row],[出]]+表格2[[#This Row],[散粉]],"-") -> 12 | I8: 10 | J8: =IFERROR(表格2[[#This Row],[重量(Kg)]]-表格2[[#This Row],[回庫]],"-") -> 2
B9: 45930 | C9: 008/1H174 | D9: =IFERROR(VLOOKUP($C9,烤漆色號編碼!$A:$C,2,FALSE),"-") -> WE2 | E9: =IFERROR(VLOOKUP($C9,當前庫存!$C:$I,5,FALSE),"-") -> 26 | F9: 4 | G9: 6 | H9: =IFERROR(VLOOKUP($C9,烤漆色號編碼!$A:$D,4,FALSE)*表格2[[#This Row],[出]]+表格2[[#This Row],[散粉]],"-") -> 106 | I9: 6 | J9: =IFERROR(表格2[[#This Row],[重量(Kg)]]-表格2[[#This Row],[回庫]],"-") -> 100
B10: 45930 | C10: 廢粉 | D10: =IFERROR(VLOOKUP($C10,烤漆色號編碼!$A:$C,2,FALSE),"-") -> - | E10: =IFERROR(VLOOKUP($C10,當前庫存!$C:$I,5,FALSE),"-") -> - | F10: 1 | H10: =IFERROR(VLOOKUP($C10,烤漆色號編碼!$A:$D,4,FALSE)*表格2[[#This Row],[出]]+表格2[[#This Row],[散粉]],"-") -> 25 | J10: =IFERROR(表格2[[#This Row],[重量(Kg)]]-表格2[[#This Row],[回庫]],"-") -> 25
B11: 45931 | C11: 4950-502 | D11: =IFERROR(VLOOKUP($C11,烤漆色號編碼!$A:$C,2,FALSE),"-") -> BK | E11: =IFERROR(VLOOKUP($C11,當前庫存!$C:$I,5,FALSE),"-") -> 4 | F11: 1 | G11: 5 | H11: =IFERROR(VLOOKUP($C11,烤漆色號編碼!$A:$D,4,FALSE)*表格2[[#This Row],[出]]+表格2[[#This Row],[散粉]],"-") -> 30 | I11: 16 | J11: =IFERROR(表格2[[#This Row],[重量(Kg)]]-表格2[[#This Row],[回庫]],"-") -> 14
B12: 45931 | C12: 4605-505 | D12: =IFERROR(VLOOKUP($C12,烤漆色號編碼!$A:$C,2,FALSE),"-") -> EBK | E12: =IFERROR(VLOOKUP($C12,當前庫存!$C:$I,5,FALSE),"-") -> 3 | G12: 10 | H12: =IFERROR(VLOOKUP($C12,烤漆色號編碼!$A:$D,4,FALSE)*表格2[[#This Row],[出]]+表格2[[#This Row],[散粉]],"-") -> 10 | I12: 9 | J12: =IFERROR(表格2[[#This Row],[重量(Kg)]]-表格2[[#This Row],[回庫]],"-") -> 1
B13: 45931 | C13: 008/1H174 | D13: =IFERROR(VLOOKUP($C13,烤漆色號編碼!$A:$C,2,FALSE),"-") -> WE2 | E13: =IFERROR(VLOOKUP($C13,當前庫存!$C:$I,5,FALSE),"-") -> 26 | F13: 4 | G13: 6 | H13: =IFERROR(VLOOKUP($C13,烤漆色號編碼!$A:$D,4,FALSE)*表格2[[#This Row],[出]]+表格2[[#This Row],[散粉]],"-") -> 106 | I13: 5 | J13: =IFERROR(表格2[[#This Row],[重量(Kg)]]-表格2[[#This Row],[回庫]],"-") -> 101
B14: 45931 | C14: 廢粉 | D14: =IFERROR(VLOOKUP($C14,烤漆色號編碼!$A:$C,2,FALSE),"-") -> - | E14: =IFERROR(VLOOKUP($C14,當前庫存!$C:$I,5,FALSE),"-") -> - | F14: 2 | H14: =IFERROR(VLOOKUP($C14,烤漆色號編碼!$A:$D,4,FALSE)*表格2[[#This Row],[出]]+表格2[[#This Row],[散粉]],"-") -> 50 | J14: =IFERROR(表格2[[#This Row],[重量(Kg)]]-表格2[[#This Row],[回庫]],"-") -> 50
B15: 45932 | C15: 無烤漆 | D15: =IFERROR(VLOOKUP($C15,烤漆色號編碼!$A:$C,2,FALSE),"-") -> - | E15: =IFERROR(VLOOKUP($C15,當前庫存!$C:$I,5,FALSE),"-") -> - | H15: =IFERROR(VLOOKUP($C15,烤漆色號編碼!$A:$D,4,FALSE)*表格2[[#This Row],[出]]+表格2[[#This Row],[散粉]],"-") -> - | J15: =IFERROR(表格2[[#This Row],[重量(Kg)]]-表格2[[#This Row],[回庫]],"-") -> -
B16: 45933 | C16: 008/1H174 | D16: =IFERROR(VLOOKUP($C16,烤漆色號編碼!$A:$C,2,FALSE),"-") -> WE2 | E16: =IFERROR(VLOOKUP($C16,當前庫存!$C:$I,5,FALSE),"-") -> 26 | F16: 2 | G16: 5 | H16: =IFERROR(VLOOKUP($C16,烤漆色號編碼!$A:$D,4,FALSE)*表格2[[#This Row],[出]]+表格2[[#This Row],[散粉]],"-") -> 55 | I16: =17+8 -> 25 | J16: =IFERROR(表格2[[#This Row],[重量(Kg)]]-表格2[[#This Row],[回庫]],"-") -> 30
B17: 45933 | C17: 4950-502 | D17: =IFERROR(VLOOKUP($C17,烤漆色號編碼!$A:$C,2,FALSE),"-") -> BK | E17: =IFERROR(VLOOKUP($C17,當前庫存!$C:$I,5,FALSE),"-") -> 4 | F17: 1 | G17: 16 | H17: =IFERROR(VLOOKUP($C17,烤漆色號編碼!$A:$D,4,FALSE)*表格2[[#This Row],[出]]+表格2[[#This Row],[散粉]],"-") -> 41 | I17: 27 | J17: =IFERROR(表格2[[#This Row],[重量(Kg)]]-表格2[[#This Row],[回庫]],"-") -> 14
B18: 45933 | C18: EL-0365T | D18: =IFERROR(VLOOKUP($C18,烤漆色號編碼!$A:$C,2,FALSE),"-") -> IGS | E18: =IFERROR(VLOOKUP($C18,當前庫存!$C:$I,5,FALSE),"-") -> 2 | F18: 3 | G18: 24 | H18: =IFERROR(VLOOKUP($C18,烤漆色號編碼!$A:$D,4,FALSE)*表格2[[#This Row],[出]]+表格2[[#This Row],[散粉]],"-") -> 99 | I18: =19+6 -> 25 | J18: =IFERROR(表格2[[#This Row],[重量(Kg)]]-表格2[[#This Row],[回庫]],"-") -> 74
B19: 45933 | C19: 廢粉 | D19: =IFERROR(VLOOKUP($C19,烤漆色號編碼!$A:$C,2,FALSE),"-") -> - | E19: =IFERROR(VLOOKUP($C19,當前庫存!$C:$I,5,FALSE),"-") -> - | F19: 2 | H19: =IFERROR(VLOOKUP($C19,烤漆色號編碼!$A:$D,4,FALSE)*表格2[[#This Row],[出]]+表格2[[#This Row],[散粉]],"-") -> 50 | J19: =IFERROR(表格2[[#This Row],[重量(Kg)]]-表格2[[#This Row],[回庫]],"-") -> 50
B20: 45934 | C20: 例假日 | D20: =IFERROR(VLOOKUP($C20,烤漆色號編碼!$A:$C,2,FALSE),"-") -> - | E20: =IFERROR(VLOOKUP($C20,當前庫存!$C:$I,5,FALSE),"-") -> - | H20: =IFERROR(VLOOKUP($C20,烤漆色號編碼!$A:$D,4,FALSE)*表格2[[#This Row],[出]]+表格2[[#This Row],[散粉]],"-") -> - | J20: =IFERROR(表格2[[#This Row],[重量(Kg)]]-表格2[[#This Row],[回庫]],"-") -> -
B21: 45935 | C21: 例假日 | D21: =IFERROR(VLOOKUP($C21,烤漆色號編碼!$A:$C,2,FALSE),"-") -> - | E21: =IFERROR(VLOOKUP($C21,當前庫存!$C:$I,5,FALSE),"-") -> - | H21: =IFERROR(VLOOKUP($C21,烤漆色號編碼!$A:$D,4,FALSE)*表格2[[#This Row],[出]]+表格2[[#This Row],[散粉]],"-") -> - | J21: =IFERROR(表格2[[#This Row],[重量(Kg)]]-表格2[[#This Row],[回庫]],"-") -> -
B22: 45936 | C22: 國定假日 | D22: =IFERROR(VLOOKUP($C22,烤漆色號編碼!$A:$C,2,FALSE),"-") -> - | E22: =IFERROR(VLOOKUP($C22,當前庫存!$C:$I,5,FALSE),"-") -> - | H22: =IFERROR(VLOOKUP($C22,烤漆色號編碼!$A:$D,4,FALSE)*表格2[[#This Row],[出]]+表格2[[#This Row],[散粉]],"-") -> - | J22: =IFERROR(表格2[[#This Row],[重量(Kg)]]-表格2[[#This Row],[回庫]],"-") -> -
B23: 45937 | C23: EL-0365T | D23: =IFERROR(VLOOKUP($C23,烤漆色號編碼!$A:$C,2,FALSE),"-") -> IGS | E23: =IFERROR(VLOOKUP($C23,當前庫存!$C:$I,5,FALSE),"-") -> 2 | G23: =19+6 -> 25 | H23: =IFERROR(VLOOKUP($C23,烤漆色號編碼!$A:$D,4,FALSE)*表格2[[#This Row],[出]]+表格2[[#This Row],[散粉]],"-") -> 25 | I23: 8 | J23: =IFERROR(表格2[[#This Row],[重量(Kg)]]-表格2[[#This Row],[回庫]],"-") -> 17
B24: 45937 | C24: 4950-502 | D24: =IFERROR(VLOOKUP($C24,烤漆色號編碼!$A:$C,2,FALSE),"-") -> BK | E24: =IFERROR(VLOOKUP($C24,當前庫存!$C:$I,5,FALSE),"-") -> 4 | G24: 27 | H24: =IFERROR(VLOOKUP($C24,烤漆色號編碼!$A:$D,4,FALSE)*表格2[[#This Row],[出]]+表格2[[#This Row],[散粉]],"-") -> 27 | I24: 22 | J24: =IFERROR(表格2[[#This Row],[重量(Kg)]]-表格2[[#This Row],[回庫]],"-") -> 5
B25: 45937 | C25: 4605-505 | D25: =IFERROR(VLOOKUP($C25,烤漆色號編碼!$A:$C,2,FALSE),"-") -> EBK | E25: =IFERROR(VLOOKUP($C25,當前庫存!$C:$I,5,FALSE),"-") -> 3 | G25: 9 | H25: =IFERROR(VLOOKUP($C25,烤漆色號編碼!$A:$D,4,FALSE)*表格2[[#This Row],[出]]+表格2[[#This Row],[散粉]],"-") -> 9 | I25: 7 | J25: =IFERROR(表格2[[#This Row],[重量(Kg)]]-表格2[[#This Row],[回庫]],"-") -> 2
B26: 45937 | C26: 008/1H174 | D26: =IFERROR(VLOOKUP($C26,烤漆色號編碼!$A:$C,2,FALSE),"-") -> WE2 | E26: =IFERROR(VLOOKUP($C26,當前庫存!$C:$I,5,FALSE),"-") -> 26 | F26: 2 | G26: =17+8 -> 25 | H26: =IFERROR(VLOOKUP($C26,烤漆色號編碼!$A:$D,4,FALSE)*表格2[[#This Row],[出]]+表格2[[#This Row],[散粉]],"-") -> 75 | I26: =11+9 -> 20 | J26: =IFERROR(表格2[[#This Row],[重量(Kg)]]-表格2[[#This Row],[回庫]],"-") -> 55
B27: 45937 | C27: 廢粉 | D27: =IFERROR(VLOOKUP($C27,烤漆色號編碼!$A:$C,2,FALSE),"-") -> - | E27: =IFERROR(VLOOKUP($C27,當前庫存!$C:$I,5,FALSE),"-") -> - | F27: 2 | H27: =IFERROR(VLOOKUP($C27,烤漆色號編碼!$A:$D,4,FALSE)*表格2[[#This Row],[出]]+表格2[[#This Row],[散粉]],"-") -> 50 | J27: =IFERROR(表格2[[#This Row],[重量(Kg)]]-表格2[[#This Row],[回庫]],"-") -> 50
B28: 45938 | C28: 無烤漆 | D28: =IFERROR(VLOOKUP($C28,烤漆色號編碼!$A:$C,2,FALSE),"-") -> - | E28: =IFERROR(VLOOKUP($C28,當前庫存!$C:$I,5,FALSE),"-") -> - | H28: =IFERROR(VLOOKUP($C28,烤漆色號編碼!$A:$D,4,FALSE)*表格2[[#This Row],[出]]+表格2[[#This Row],[散粉]],"-") -> - | J28: =IFERROR(表格2[[#This Row],[重量(Kg)]]-表格2[[#This Row],[回庫]],"-") -> -
B29: 45939 | C29: 008/1H174 | D29: =IFERROR(VLOOKUP($C29,烤漆色號編碼!$A:$C,2,FALSE),"-") -> WE2 | E29: =IFERROR(VLOOKUP($C29,當前庫存!$C:$I,5,FALSE),"-") -> 26 | F29: 1 | G29: =11+9 -> 20 | H29: =IFERROR(VLOOKUP($C29,烤漆色號編碼!$A:$D,4,FALSE)*表格2[[#This Row],[出]]+表格2[[#This Row],[散粉]],"-") -> 45 | I29: 5 | J29: =IFERROR(表格2[[#This Row],[重量(Kg)]]-表格2[[#This Row],[回庫]],"-") -> 40
B30: 45939 | C30: EL-0365T | D30: =IFERROR(VLOOKUP($C30,烤漆色號編碼!$A:$C,2,FALSE),"-") -> IGS | E30: =IFERROR(VLOOKUP($C30,當前庫存!$C:$I,5,FALSE),"-") -> 2 | F30: 1 | H30: =IFERROR(VLOOKUP($C30,烤漆色號編碼!$A:$D,4,FALSE)*表格2[[#This Row],[出]]+表格2[[#This Row],[散粉]],"-") -> 25 | I30: 7 | J30: =IFERROR(表格2[[#This Row],[重量(Kg)]]-表格2[[#This Row],[回庫]],"-") -> 18
B31: 45939 | C31: K-91097G | D31: =IFERROR(VLOOKUP($C31,烤漆色號編碼!$A:$C,2,FALSE),"-") -> BKS1 | E31: =IFERROR(VLOOKUP($C31,當前庫存!$C:$I,5,FALSE),"-") -> 17 | F31: 1 | G31: 25 | H31: =IFERROR(VLOOKUP($C31,烤漆色號編碼!$A:$D,4,FALSE)*表格2[[#This Row],[出]]+表格2[[#This Row],[散粉]],"-") -> 50 | I31: 18 | J31: =IFERROR(表格2[[#This Row],[重量(Kg)]]-表格2[[#This Row],[回庫]],"-") -> 32
B32: 45939 | C32: 4950-502 | D32: =IFERROR(VLOOKUP($C32,烤漆色號編碼!$A:$C,2,FALSE),"-") -> BK | E32: =IFERROR(VLOOKUP($C32,當前庫存!$C:$I,5,FALSE),"-") -> 4 | G32: 22 | H32: =IFERROR(VLOOKUP($C32,烤漆色號編碼!$A:$D,4,FALSE)*表格2[[#This Row],[出]]+表格2[[#This Row],[散粉]],"-") -> 22 | I32: 21 | J32: =IFERROR(表格2[[#This Row],[重量(Kg)]]-表格2[[#This Row],[回庫]],"-") -> 1
B33: 45939 | C33: 廢粉 | D33: =IFERROR(VLOOKUP($C33,烤漆色號編碼!$A:$C,2,FALSE),"-") -> - | E33: =IFERROR(VLOOKUP($C33,當前庫存!$C:$I,5,FALSE),"-") -> - | F33: 2 | H33: =IFERROR(VLOOKUP($C33,烤漆色號編碼!$A:$D,4,FALSE)*表格2[[#This Row],[出]]+表格2[[#This Row],[散粉]],"-") -> 50 | J33: =IFERROR(表格2[[#This Row],[重量(Kg)]]-表格2[[#This Row],[回庫]],"-") -> 50
B34: 45940 | C34: 國定假日 | D34: =IFERROR(VLOOKUP($C34,烤漆色號編碼!$A:$C,2,FALSE),"-") -> - | E34: =IFERROR(VLOOKUP($C34,當前庫存!$C:$I,5,FALSE),"-") -> - | H34: =IFERROR(VLOOKUP($C34,烤漆色號編碼!$A:$D,4,FALSE)*表格2[[#This Row],[出]]+表格2[[#This Row],[散粉]],"-") -> - | J34: =IFERROR(表格2[[#This Row],[重量(Kg)]]-表格2[[#This Row],[回庫]],"-") -> -
B35: 45941 | C35: 例假日 | D35: =IFERROR(VLOOKUP($C35,烤漆色號編碼!$A:$C,2,FALSE),"-") -> - | E35: =IFERROR(VLOOKUP($C35,當前庫存!$C:$I,5,FALSE),"-") -> - | H35: =IFERROR(VLOOKUP($C35,烤漆色號編碼!$A:$D,4,FALSE)*表格2[[#This Row],[出]]+表格2[[#This Row],[散粉]],"-") -> - | J35: =IFERROR(表格2[[#This Row],[重量(Kg)]]-表格2[[#This Row],[回庫]],"-") -> -
B36: 45942 | C36: 例假日 | D36: =IFERROR(VLOOKUP($C36,烤漆色號編碼!$A:$C,2,FALSE),"-") -> - | E36: =IFERROR(VLOOKUP($C36,當前庫存!$C:$I,5,FALSE),"-") -> - | H36: =IFERROR(VLOOKUP($C36,烤漆色號編碼!$A:$D,4,FALSE)*表格2[[#This Row],[出]]+表格2[[#This Row],[散粉]],"-") -> - | J36: =IFERROR(表格2[[#This Row],[重量(Kg)]]-表格2[[#This Row],[回庫]],"-") -> -
B37: 45943 | C37: K-91097G | D37: =IFERROR(VLOOKUP($C37,烤漆色號編碼!$A:$C,2,FALSE),"-") -> BKS1 | E37: =IFERROR(VLOOKUP($C37,當前庫存!$C:$I,5,FALSE),"-") -> 17 | F37: 2 | G37: =18+21 -> 39 | H37: =IFERROR(VLOOKUP($C37,烤漆色號編碼!$A:$D,4,FALSE)*表格2[[#This Row],[出]]+表格2[[#This Row],[散粉]],"-") -> 89 | I37: =6+6 -> 12 | J37: =IFERROR(表格2[[#This Row],[重量(Kg)]]-表格2[[#This Row],[回庫]],"-") -> 77
B38: 45943 | C38: 008/1H174 | D38: =IFERROR(VLOOKUP($C38,烤漆色號編碼!$A:$C,2,FALSE),"-") -> WE2 | E38: =IFERROR(VLOOKUP($C38,當前庫存!$C:$I,5,FALSE),"-") -> 26 | F38: 4 | G38: 5 | H38: =IFERROR(VLOOKUP($C38,烤漆色號編碼!$A:$D,4,FALSE)*表格2[[#This Row],[出]]+表格2[[#This Row],[散粉]],"-") -> 105 | I38: =12+6 -> 18 | J38: =IFERROR(表格2[[#This Row],[重量(Kg)]]-表格2[[#This Row],[回庫]],"-") -> 87
B39: 45943 | C39: 廢粉 | D39: =IFERROR(VLOOKUP($C39,烤漆色號編碼!$A:$C,2,FALSE),"-") -> - | E39: =IFERROR(VLOOKUP($C39,當前庫存!$C:$I,5,FALSE),"-") -> - | F39: 2 | H39: =IFERROR(VLOOKUP($C39,烤漆色號編碼!$A:$D,4,FALSE)*表格2[[#This Row],[出]]+表格2[[#This Row],[散粉]],"-") -> 50 | J39: =IFERROR(表格2[[#This Row],[重量(Kg)]]-表格2[[#This Row],[回庫]],"-") -> 50
B40: 45944 | C40: 008/2H056 | D40: =IFERROR(VLOOKUP($C40,烤漆色號編碼!$A:$C,2,FALSE),"-") -> YW1 | E40: =IFERROR(VLOOKUP($C40,當前庫存!$C:$I,5,FALSE),"-") -> 12 | G40: 5 | H40: =IFERROR(VLOOKUP($C40,烤漆色號編碼!$A:$D,4,FALSE)*表格2[[#This Row],[出]]+表格2[[#This Row],[散粉]],"-") -> 5 | I40: 4 | J40: =IFERROR(表格2[[#This Row],[重量(Kg)]]-表格2[[#This Row],[回庫]],"-") -> 1
B41: 45944 | C41: 780-9B65 | D41: =IFERROR(VLOOKUP($C41,烤漆色號編碼!$A:$C,2,FALSE),"-") -> ATG | E41: =IFERROR(VLOOKUP($C41,當前庫存!$C:$I,5,FALSE),"-") -> 3 | G41: 21 | H41: =IFERROR(VLOOKUP($C41,烤漆色號編碼!$A:$D,4,FALSE)*表格2[[#This Row],[出]]+表格2[[#This Row],[散粉]],"-") -> 21 | I41: 20 | J41: =IFERROR(表格2[[#This Row],[重量(Kg)]]-表格2[[#This Row],[回庫]],"-") -> 1
...

Sheet 當前庫存
C2: 紀錄表 | D2: 當前庫存 | E2: 期初庫存 | F2: 採購入庫 | G2: =TODAY() -> 46300 | H2: =TEXT(WEEKDAY(每日用粉紀錄表!#REF!,1),"aaaa") -> #REF!
B3: NO: | C3: 粉號 | D3: 色系 | E3: 代號 | F3: 散粉(KG) | G3: 當前庫存 | H3: 安全庫存（設置） | I3: 建議購入 | J3: 總數量
B4: =MAX($B$3:B3)+1 -> 1 | C4: =IF(烤漆色號編碼!A2="","-",烤漆色號編碼!A2) -> DP-11485 | D4: =IF(烤漆色號編碼!C2="","-",烤漆色號編碼!C2) -> 白亮光 | E4: =IF(烤漆色號編碼!B2="","-",烤漆色號編碼!B2) -> WE | F4: =SUMIFS(期初庫存!F:F,期初庫存!C:C,C4)+SUMIFS(採購入庫!H:H,採購入庫!D:D,C4)-SUMIFS(借出!H:H,借出!D:D,C4)-SUMIFS(每日用粉紀錄表!G:G,每日用粉紀錄表!C:C,C4)+SUMIFS(歸還!H:H,歸還!D:D,C4)+SUMIFS(每日用粉紀錄表!I:I,每日用粉紀錄表!C:C,C4) -> 38 | G4: =SUMIFS(期初庫存!G:G,期初庫存!C:C,C4)+SUMIFS(採購入庫!G:G,採購入庫!D:D,C4)-SUMIFS(每日用粉紀錄表!F:F,每日用粉紀錄表!C:C,C4)-SUMIFS(借出!G:G,借出!D:D,C4)+SUMIFS(歸還!G:G,歸還!D:D,C4) -> 1 | I4: =IF(H4>G4,"採購","否") -> 否 | J4: =IFERROR($G4*25+$F4,"-") -> 63
B5: =MAX($B$3:B4)+1 -> 2 | C5: =IF(烤漆色號編碼!A3="","-",烤漆色號編碼!A3) -> DP-1856 | D5: =IF(烤漆色號編碼!C3="","-",烤漆色號編碼!C3) -> 灰白 | E5: =IF(烤漆色號編碼!B3="","-",烤漆色號編碼!B3) -> WE1 | F5: =SUMIFS(期初庫存!F:F,期初庫存!C:C,C5)+SUMIFS(採購入庫!H:H,採購入庫!D:D,C5)-SUMIFS(借出!H:H,借出!D:D,C5)-SUMIFS(每日用粉紀錄表!G:G,每日用粉紀錄表!C:C,C5)+SUMIFS(歸還!H:H,歸還!D:D,C5)+SUMIFS(每日用粉紀錄表!I:I,每日用粉紀錄表!C:C,C5) -> 12 | G5: =SUMIFS(期初庫存!G:G,期初庫存!C:C,C5)+SUMIFS(採購入庫!G:G,採購入庫!D:D,C5)-SUMIFS(每日用粉紀錄表!F:F,每日用粉紀錄表!C:C,C5)-SUMIFS(借出!G:G,借出!D:D,C5)+SUMIFS(歸還!G:G,歸還!D:D,C5) -> 1 | I5: =IF(H5>G5,"採購","否") -> 否 | J5: =IFERROR($G5*25+$F5,"-") -> 37
B6: =MAX($B$3:B5)+1 -> 3 | C6: =IF(烤漆色號編碼!A4="","-",烤漆色號編碼!A4) -> O-5905 | D6: =IF(烤漆色號編碼!C4="","-",烤漆色號編碼!C4) -> 黃亮光 | E6: =IF(烤漆色號編碼!B4="","-",烤漆色號編碼!B4) -> 換粉 | F6: =SUMIFS(期初庫存!F:F,期初庫存!C:C,C6)+SUMIFS(採購入庫!H:H,採購入庫!D:D,C6)-SUMIFS(借出!H:H,借出!D:D,C6)-SUMIFS(每日用粉紀錄表!G:G,每日用粉紀錄表!C:C,C6)+SUMIFS(歸還!H:H,歸還!D:D,C6)+SUMIFS(每日用粉紀錄表!I:I,每日用粉紀錄表!C:C,C6) -> 0 | G6: =SUMIFS(期初庫存!G:G,期初庫存!C:C,C6)+SUMIFS(採購入庫!G:G,採購入庫!D:D,C6)-SUMIFS(每日用粉紀錄表!F:F,每日用粉紀錄表!C:C,C6)-SUMIFS(借出!G:G,借出!D:D,C6)+SUMIFS(歸還!G:G,歸還!D:D,C6) -> 0 | I6: =IF(H6>G6,"採購","否") -> 否 | J6: =IFERROR($G6*25+$F6,"-") -> 0
B7: =MAX($B$3:B6)+1 -> 4 | C7: =IF(烤漆色號編碼!A5="","-",烤漆色號編碼!A5) -> New O-5905 | D7: =IF(烤漆色號編碼!C5="","-",烤漆色號編碼!C5) -> 黃亮光 | E7: =IF(烤漆色號編碼!B5="","-",烤漆色號編碼!B5) -> 換粉 | F7: =SUMIFS(期初庫存!F:F,期初庫存!C:C,C7)+SUMIFS(採購入庫!H:H,採購入庫!D:D,C7)-SUMIFS(借出!H:H,借出!D:D,C7)-SUMIFS(每日用粉紀錄表!G:G,每日用粉紀錄表!C:C,C7)+SUMIFS(歸還!H:H,歸還!D:D,C7)+SUMIFS(每日用粉紀錄表!I:I,每日用粉紀錄表!C:C,C7) -> 7 | G7: =SUMIFS(期初庫存!G:G,期初庫存!C:C,C7)+SUMIFS(採購入庫!G:G,採購入庫!D:D,C7)-SUMIFS(每日用粉紀錄表!F:F,每日用粉紀錄表!C:C,C7)-SUMIFS(借出!G:G,借出!D:D,C7)+SUMIFS(歸還!G:G,歸還!D:D,C7) -> 2 | I7: =IF(H7>G7,"採購","否") -> 否 | J7: =IFERROR($G7*25+$F7,"-") -> 57
B8: =MAX($B$3:B7)+1 -> 5 | C8: =IF(烤漆色號編碼!A6="","-",烤漆色號編碼!A6) -> 790-41540H | D8: =IF(烤漆色號編碼!C6="","-",烤漆色號編碼!C6) -> 黃錘紋 | E8: =IF(烤漆色號編碼!B6="","-",烤漆色號編碼!B6) -> YWH | F8: =SUMIFS(期初庫存!F:F,期初庫存!C:C,C8)+SUMIFS(採購入庫!H:H,採購入庫!D:D,C8)-SUMIFS(借出!H:H,借出!D:D,C8)-SUMIFS(每日用粉紀錄表!G:G,每日用粉紀錄表!C:C,C8)+SUMIFS(歸還!H:H,歸還!D:D,C8)+SUMIFS(每日用粉紀錄表!I:I,每日用粉紀錄表!C:C,C8) -> 27 | G8: =SUMIFS(期初庫存!G:G,期初庫存!C:C,C8)+SUMIFS(採購入庫!G:G,採購入庫!D:D,C8)-SUMIFS(每日用粉紀錄表!F:F,每日用粉紀錄表!C:C,C8)-SUMIFS(借出!G:G,借出!D:D,C8)+SUMIFS(歸還!G:G,歸還!D:D,C8) -> 0 | H8: 1 | I8: =IF(H8>G8,"採購","否") -> 採購 | J8: =IFERROR($G8*25+$F8,"-") -> 27
B9: =MAX($B$3:B8)+1 -> 6 | C9: =IF(烤漆色號編碼!A7="","-",烤漆色號編碼!A7) -> 780-310AT | D9: =IF(烤漆色號編碼!C7="","-",烤漆色號編碼!C7) -> 法拉利紅 | E9: =IF(烤漆色號編碼!B7="","-",烤漆色號編碼!B7) -> RD | F9: =SUMIFS(期初庫存!F:F,期初庫存!C:C,C9)+SUMIFS(採購入庫!H:H,採購入庫!D:D,C9)-SUMIFS(借出!H:H,借出!D:D,C9)-SUMIFS(每日用粉紀錄表!G:G,每日用粉紀錄表!C:C,C9)+SUMIFS(歸還!H:H,歸還!D:D,C9)+SUMIFS(每日用粉紀錄表!I:I,每日用粉紀錄表!C:C,C9) -> 12 | G9: =SUMIFS(期初庫存!G:G,期初庫存!C:C,C9)+SUMIFS(採購入庫!G:G,採購入庫!D:D,C9)-SUMIFS(每日用粉紀錄表!F:F,每日用粉紀錄表!C:C,C9)-SUMIFS(借出!G:G,借出!D:D,C9)+SUMIFS(歸還!G:G,歸還!D:D,C9) -> 3 | H9: 1 | I9: =IF(H9>G9,"採購","否") -> 否 | J9: =IFERROR($G9*25+$F9,"-") -> 87
B10: =MAX($B$3:B9)+1 -> 7 | C10: =IF(烤漆色號編碼!A8="","-",烤漆色號編碼!A8) -> LT-90442 | D10: =IF(烤漆色號編碼!C8="","-",烤漆色號編碼!C8) -> 藍色 | E10: =IF(烤漆色號編碼!B8="","-",烤漆色號編碼!B8) -> BE | F10: =SUMIFS(期初庫存!F:F,期初庫存!C:C,C10)+SUMIFS(採購入庫!H:H,採購入庫!D:D,C10)-SUMIFS(借出!H:H,借出!D:D,C10)-SUMIFS(每日用粉紀錄表!G:G,每日用粉紀錄表!C:C,C10)+SUMIFS(歸還!H:H,歸還!D:D,C10)+SUMIFS(每日用粉紀錄表!I:I,每日用粉紀錄表!C:C,C10) -> 3 | G10: =SUMIFS(期初庫存!G:G,期初庫存!C:C,C10)+SUMIFS(採購入庫!G:G,採購入庫!D:D,C10)-SUMIFS(每日用粉紀錄表!F:F,每日用粉紀錄表!C:C,C10)-SUMIFS(借出!G:G,借出!D:D,C10)+SUMIFS(歸還!G:G,歸還!D:D,C10) -> 2 | H10: 1 | I10: =IF(H10>G10,"採購","否") -> 否 | J10: =IFERROR($G10*25+$F10,"-") -> 53
B11: =MAX($B$3:B10)+1 -> 8 | C11: =IF(烤漆色號編碼!A9="","-",烤漆色號編碼!A9) -> 770-739 | D11: =IF(烤漆色號編碼!C9="","-",烤漆色號編碼!C9) -> 豔藍-孔雀藍 | E11: =IF(烤漆色號編碼!B9="","-",烤漆色號編碼!B9) -> BEG | F11: =SUMIFS(期初庫存!F:F,期初庫存!C:C,C11)+SUMIFS(採購入庫!H:H,採購入庫!D:D,C11)-SUMIFS(借出!H:H,借出!D:D,C11)-SUMIFS(每日用粉紀錄表!G:G,每日用粉紀錄表!C:C,C11)+SUMIFS(歸還!H:H,歸還!D:D,C11)+SUMIFS(每日用粉紀錄表!I:I,每日用粉紀錄表!C:C,C11) -> 5 | G11: =SUMIFS(期初庫存!G:G,期初庫存!C:C,C11)+SUMIFS(採購入庫!G:G,採購入庫!D:D,C11)-SUMIFS(每日用粉紀錄表!F:F,每日用粉紀錄表!C:C,C11)-SUMIFS(借出!G:G,借出!D:D,C11)+SUMIFS(歸還!G:G,歸還!D:D,C11) -> 5 | H11: 1 | I11: =IF(H11>G11,"採購","否") -> 否 | J11: =IFERROR($G11*25+$F11,"-") -> 130
B12: =MAX($B$3:B11)+1 -> 9 | C12: =IF(烤漆色號編碼!A10="","-",烤漆色號編碼!A10) -> 4950-502 | D12: =IF(烤漆色號編碼!C10="","-",烤漆色號編碼!C10) -> 黑平光 | E12: =IF(烤漆色號編碼!B10="","-",烤漆色號編碼!B10) -> BK | F12: =SUMIFS(期初庫存!F:F,期初庫存!C:C,C12)+SUMIFS(採購入庫!H:H,採購入庫!D:D,C12)-SUMIFS(借出!H:H,借出!D:D,C12)-SUMIFS(每日用粉紀錄表!G:G,每日用粉紀錄表!C:C,C12)+SUMIFS(歸還!H:H,歸還!D:D,C12)+SUMIFS(每日用粉紀錄表!I:I,每日用粉紀錄表!C:C,C12) -> 11 | G12: =SUMIFS(期初庫存!G:G,期初庫存!C:C,C12)+SUMIFS(採購入庫!G:G,採購入庫!D:D,C12)-SUMIFS(每日用粉紀錄表!F:F,每日用粉紀錄表!C:C,C12)-SUMIFS(借出!G:G,借出!D:D,C12)+SUMIFS(歸還!G:G,歸還!D:D,C12) -> 4 | H12: 1 | I12: =IF(H12>G12,"採購","否") -> 否 | J12: =IFERROR($G12*25+$F12,"-") -> 111
B13: =MAX($B$3:B12)+1 -> 10 | C13: =IF(烤漆色號編碼!A11="","-",烤漆色號編碼!A11) -> EN-402T | D13: =IF(烤漆色號編碼!C11="","-",烤漆色號編碼!C11) -> 黑錘紋 | E13: =IF(烤漆色號編碼!B11="","-",烤漆色號編碼!B11) -> BKH | F13: =SUMIFS(期初庫存!F:F,期初庫存!C:C,C13)+SUMIFS(採購入庫!H:H,採購入庫!D:D,C13)-SUMIFS(借出!H:H,借出!D:D,C13)-SUMIFS(每日用粉紀錄表!G:G,每日用粉紀錄表!C:C,C13)+SUMIFS(歸還!H:H,歸還!D:D,C13)+SUMIFS(每日用粉紀錄表!I:I,每日用粉紀錄表!C:C,C13) -> 36 | G13: =SUMIFS(期初庫存!G:G,期初庫存!C:C,C13)+SUMIFS(採購入庫!G:G,採購入庫!D:D,C13)-SUMIFS(每日用粉紀錄表!F:F,每日用粉紀錄表!C:C,C13)-SUMIFS(借出!G:G,借出!D:D,C13)+SUMIFS(歸還!G:G,歸還!D:D,C13) -> 0 | H13: 1 | I13: =IF(H13>G13,"採購","否") -> 採購 | J13: =IFERROR($G13*25+$F13,"-") -> 36
B14: =MAX($B$3:B13)+1 -> 11 | C14: =IF(烤漆色號編碼!A12="","-",烤漆色號編碼!A12) -> K-91097G | D14: =IF(烤漆色號編碼!C12="","-",烤漆色號編碼!C12) -> 新黑砂 | E14: =IF(烤漆色號編碼!B12="","-",烤漆色號編碼!B12) -> BKS1 | F14: =SUMIFS(期初庫存!F:F,期初庫存!C:C,C14)+SUMIFS(採購入庫!H:H,採購入庫!D:D,C14)-SUMIFS(借出!H:H,借出!D:D,C14)-SUMIFS(每日用粉紀錄表!G:G,每日用粉紀錄表!C:C,C14)+SUMIFS(歸還!H:H,歸還!D:D,C14)+SUMIFS(每日用粉紀錄表!I:I,每日用粉紀錄表!C:C,C14) -> 3 | G14: =SUMIFS(期初庫存!G:G,期初庫存!C:C,C14)+SUMIFS(採購入庫!G:G,採購入庫!D:D,C14)-SUMIFS(每日用粉紀錄表!F:F,每日用粉紀錄表!C:C,C14)-SUMIFS(借出!G:G,借出!D:D,C14)+SUMIFS(歸還!G:G,歸還!D:D,C14) -> 17 | H14: 8 | I14: =IF(H14>G14,"採購","否") -> 否 | J14: =IFERROR($G14*25+$F14,"-") -> 428
B15: =MAX($B$3:B14)+1 -> 12 | C15: =IF(烤漆色號編碼!A13="","-",烤漆色號編碼!A13) -> 780-45510H | D15: =IF(烤漆色號編碼!C13="","-",烤漆色號編碼!C13) -> 黑砂 | E15: =IF(烤漆色號編碼!B13="","-",烤漆色號編碼!B13) -> 換粉 | F15: =SUMIFS(期初庫存!F:F,期初庫存!C:C,C15)+SUMIFS(採購入庫!H:H,採購入庫!D:D,C15)-SUMIFS(借出!H:H,借出!D:D,C15)-SUMIFS(每日用粉紀錄表!G:G,每日用粉紀錄表!C:C,C15)+SUMIFS(歸還!H:H,歸還!D:D,C15)+SUMIFS(每日用粉紀錄表!I:I,每日用粉紀錄表!C:C,C15) -> 0 | G15: =SUMIFS(期初庫存!G:G,期初庫存!C:C,C15)+SUMIFS(採購入庫!G:G,採購入庫!D:D,C15)-SUMIFS(每日用粉紀錄表!F:F,每日用粉紀錄表!C:C,C15)-SUMIFS(借出!G:G,借出!D:D,C15)+SUMIFS(歸還!G:G,歸還!D:D,C15) -> 0 | I15: =IF(H15>G15,"採購","否") -> 否 | J15: =IFERROR($G15*25+$F15,"-") -> 0
B16: =MAX($B$3:B15)+1 -> 13 | C16: =IF(烤漆色號編碼!A14="","-",烤漆色號編碼!A14) -> 4605-505 | D16: =IF(烤漆色號編碼!C14="","-",烤漆色號編碼!C14) -> 消光黑 | E16: =IF(烤漆色號編碼!B14="","-",烤漆色號編碼!B14) -> EBK | F16: =SUMIFS(期初庫存!F:F,期初庫存!C:C,C16)+SUMIFS(採購入庫!H:H,採購入庫!D:D,C16)-SUMIFS(借出!H:H,借出!D:D,C16)-SUMIFS(每日用粉紀錄表!G:G,每日用粉紀錄表!C:C,C16)+SUMIFS(歸還!H:H,歸還!D:D,C16)+SUMIFS(每日用粉紀錄表!I:I,每日用粉紀錄表!C:C,C16) -> 26 | G16: =SUMIFS(期初庫存!G:G,期初庫存!C:C,C16)+SUMIFS(採購入庫!G:G,採購入庫!D:D,C16)-SUMIFS(每日用粉紀錄表!F:F,每日用粉紀錄表!C:C,C16)-SUMIFS(借出!G:G,借出!D:D,C16)+SUMIFS(歸還!G:G,歸還!D:D,C16) -> 3 | H16: 1 | I16: =IF(H16>G16,"採購","否") -> 否 | J16: =IFERROR($G16*25+$F16,"-") -> 101
B17: =MAX($B$3:B16)+1 -> 14 | C17: =IF(烤漆色號編碼!A15="","-",烤漆色號編碼!A15) -> O-9850GSNB | D17: =IF(烤漆色號編碼!C15="","-",烤漆色號編碼!C15) -> 黑砂閃銀 | E17: =IF(烤漆色號編碼!B15="","-",烤漆色號編碼!B15) -> BKSA | F17: =SUMIFS(期初庫存!F:F,期初庫存!C:C,C17)+SUMIFS(採購入庫!H:H,採購入庫!D:D,C17)-SUMIFS(借出!H:H,借出!D:D,C17)-SUMIFS(每日用粉紀錄表!G:G,每日用粉紀錄表!C:C,C17)+SUMIFS(歸還!H:H,歸還!D:D,C17)+SUMIFS(每日用粉紀錄表!I:I,每日用粉紀錄表!C:C,C17) -> 65 | G17: =SUMIFS(期初庫存!G:G,期初庫存!C:C,C17)+SUMIFS(採購入庫!G:G,採購入庫!D:D,C17)-SUMIFS(每日用粉紀錄表!F:F,每日用粉紀錄表!C:C,C17)-SUMIFS(借出!G:G,借出!D:D,C17)+SUMIFS(歸還!G:G,歸還!D:D,C17) -> 1 | H17: 1 | I17: =IF(H17>G17,"採購","否") -> 否 | J17: =IFERROR($G17*25+$F17,"-") -> 90
B18: =MAX($B$3:B17)+1 -> 15 | C18: =IF(烤漆色號編碼!A16="","-",烤漆色號編碼!A16) -> K-9287S | D18: =IF(烤漆色號編碼!C16="","-",烤漆色號編碼!C16) -> 黑閃銀 | E18: =IF(烤漆色號編碼!B16="","-",烤漆色號編碼!B16) -> BKSA1 | F18: =SUMIFS(期初庫存!F:F,期初庫存!C:C,C18)+SUMIFS(採購入庫!H:H,採購入庫!D:D,C18)-SUMIFS(借出!H:H,借出!D:D,C18)-SUMIFS(每日用粉紀錄表!G:G,每日用粉紀錄表!C:C,C18)+SUMIFS(歸還!H:H,歸還!D:D,C18)+SUMIFS(每日用粉紀錄表!I:I,每日用粉紀錄表!C:C,C18) -> 8 | G18: =SUMIFS(期初庫存!G:G,期初庫存!C:C,C18)+SUMIFS(採購入庫!G:G,採購入庫!D:D,C18)-SUMIFS(每日用粉紀錄表!F:F,每日用粉紀錄表!C:C,C18)-SUMIFS(借出!G:G,借出!D:D,C18)+SUMIFS(歸還!G:G,歸還!D:D,C18) -> 2 | H18: 1 | I18: =IF(H18>G18,"採購","否") -> 否 | J18: =IFERROR($G18*25+$F18,"-") -> 58
B19: =MAX($B$3:B18)+1 -> 16 | C19: =IF(烤漆色號編碼!A17="","-",烤漆色號編碼!A17) -> EL-0365T | D19: =IF(烤漆色號編碼!C17="","-",烤漆色號編碼!C17) -> 鐵灰砂 | E19: =IF(烤漆色號編碼!B17="","-",烤漆色號編碼!B17) -> IGS | F19: =SUMIFS(期初庫存!F:F,期初庫存!C:C,C19)+SUMIFS(採購入庫!H:H,採購入庫!D:D,C19)-SUMIFS(借出!H:H,借出!D:D,C19)-SUMIFS(每日用粉紀錄表!G:G,每日用粉紀錄表!C:C,C19)+SUMIFS(歸還!H:H,歸還!D:D,C19)+SUMIFS(每日用粉紀錄表!I:I,每日用粉紀錄表!C:C,C19) -> 22 | G19: =SUMIFS(期初庫存!G:G,期初庫存!C:C,C19)+SUMIFS(採購入庫!G:G,採購入庫!D:D,C19)-SUMIFS(每日用粉紀錄表!F:F,每日用粉紀錄表!C:C,C19)-SUMIFS(借出!G:G,借出!D:D,C19)+SUMIFS(歸還!G:G,歸還!D:D,C19) -> 2 | H19: 6 | I19: =IF(H19>G19,"採購","否") -> 採購 | J19: =IFERROR($G19*25+$F19,"-") -> 72
B20: =MAX($B$3:B19)+1 -> 17 | C20: =IF(烤漆色號編碼!A18="","-",烤漆色號編碼!A18) -> O-22170G | D20: =IF(烤漆色號編碼!C18="","-",烤漆色號編碼!C18) -> 深灰砂 | E20: =IF(烤漆色號編碼!B18="","-",烤漆色號編碼!B18) -> DGS | F20: =SUMIFS(期初庫存!F:F,期初庫存!C:C,C20)+SUMIFS(採購入庫!H:H,採購入庫!D:D,C20)-SUMIFS(借出!H:H,借出!D:D,C20)-SUMIFS(每日用粉紀錄表!G:G,每日用粉紀錄表!C:C,C20)+SUMIFS(歸還!H:H,歸還!D:D,C20)+SUMIFS(每日用粉紀錄表!I:I,每日用粉紀錄表!C:C,C20) -> 17 | G20: =SUMIFS(期初庫存!G:G,期初庫存!C:C,C20)+SUMIFS(採購入庫!G:G,採購入庫!D:D,C20)-SUMIFS(每日用粉紀錄表!F:F,每日用粉紀錄表!C:C,C20)-SUMIFS(借出!G:G,借出!D:D,C20)+SUMIFS(歸還!G:G,歸還!D:D,C20) -> 8 | H20: 6 | I20: =IF(H20>G20,"採購","否") -> 否 | J20: =IFERROR($G20*25+$F20,"-") -> 217
B21: =MAX($B$3:B20)+1 -> 18 | C21: =IF(烤漆色號編碼!A19="","-",烤漆色號編碼!A19) -> O-200SB | D21: =IF(烤漆色號編碼!C19="","-",烤漆色號編碼!C19) -> 閃銀 | E21: =IF(烤漆色號編碼!B19="","-",烤漆色號編碼!B19) -> 無粉 | F21: =SUMIFS(期初庫存!F:F,期初庫存!C:C,C21)+SUMIFS(採購入庫!H:H,採購入庫!D:D,C21)-SUMIFS(借出!H:H,借出!D:D,C21)-SUMIFS(每日用粉紀錄表!G:G,每日用粉紀錄表!C:C,C21)+SUMIFS(歸還!H:H,歸還!D:D,C21)+SUMIFS(每日用粉紀錄表!I:I,每日用粉紀錄表!C:C,C21) -> 0 | G21: =SUMIFS(期初庫存!G:G,期初庫存!C:C,C21)+SUMIFS(採購入庫!G:G,採購入庫!D:D,C21)-SUMIFS(每日用粉紀錄表!F:F,每日用粉紀錄表!C:C,C21)-SUMIFS(借出!G:G,借出!D:D,C21)+SUMIFS(歸還!G:G,歸還!D:D,C21) -> 0 | I21: =IF(H21>G21,"採購","否") -> 否 | J21: =IFERROR($G21*25+$F21,"-") -> 0
B22: =MAX($B$3:B21)+1 -> 19 | C22: =IF(烤漆色號編碼!A20="","-",烤漆色號編碼!A20) -> K-5257CSB | D22: =IF(烤漆色號編碼!C20="","-",烤漆色號編碼!C20) -> 新閃銀 | E22: =IF(烤漆色號編碼!B20="","-",烤漆色號編碼!B20) -> 換粉 | F22: =SUMIFS(期初庫存!F:F,期初庫存!C:C,C22)+SUMIFS(採購入庫!H:H,採購入庫!D:D,C22)-SUMIFS(借出!H:H,借出!D:D,C22)-SUMIFS(每日用粉紀錄表!G:G,每日用粉紀錄表!C:C,C22)+SUMIFS(歸還!H:H,歸還!D:D,C22)+SUMIFS(每日用粉紀錄表!I:I,每日用粉紀錄表!C:C,C22) -> 44 | G22: =SUMIFS(期初庫存!G:G,期初庫存!C:C,C22)+SUMIFS(採購入庫!G:G,採購入庫!D:D,C22)-SUMIFS(每日用粉紀錄表!F:F,每日用粉紀錄表!C:C,C22)-SUMIFS(借出!G:G,借出!D:D,C22)+SUMIFS(歸還!G:G,歸還!D:D,C22) -> 2 | I22: =IF(H22>G22,"採購","否") -> 否 | J22: =IFERROR($G22*25+$F22,"-") -> 94
B23: =MAX($B$3:B22)+1 -> 20 | C23: =IF(烤漆色號編碼!A21="","-",烤漆色號編碼!A21) -> K-4654 | D23: =IF(烤漆色號編碼!C21="","-",烤漆色號編碼!C21) -> 紫色 | E23: =IF(烤漆色號編碼!B21="","-",烤漆色號編碼!B21) -> PEL | F23: =SUMIFS(期初庫存!F:F,期初庫存!C:C,C23)+SUMIFS(採購入庫!H:H,採購入庫!D:D,C23)-SUMIFS(借出!H:H,借出!D:D,C23)-SUMIFS(每日用粉紀錄表!G:G,每日用粉紀錄表!C:C,C23)+SUMIFS(歸還!H:H,歸還!D:D,C23)+SUMIFS(每日用粉紀錄表!I:I,每日用粉紀錄表!C:C,C23) -> 34 | G23: =SUMIFS(期初庫存!G:G,期初庫存!C:C,C23)+SUMIFS(採購入庫!G:G,採購入庫!D:D,C23)-SUMIFS(每日用粉紀錄表!F:F,每日用粉紀錄表!C:C,C23)-SUMIFS(借出!G:G,借出!D:D,C23)+SUMIFS(歸還!G:G,歸還!D:D,C23) -> 2 | H23: 1 | I23: =IF(H23>G23,"採購","否") -> 否 | J23: =IFERROR($G23*25+$F23,"-") -> 84
B24: =MAX($B$3:B23)+1 -> 21 | C24: =IF(烤漆色號編碼!A22="","-",烤漆色號編碼!A22) -> 780-9B65 | D24: =IF(烤漆色號編碼!C22="","-",烤漆色號編碼!C22) -> 銀灰 | E24: =IF(烤漆色號編碼!B22="","-",烤漆色號編碼!B22) -> ATG | F24: =SUMIFS(期初庫存!F:F,期初庫存!C:C,C24)+SUMIFS(採購入庫!H:H,採購入庫!D:D,C24)-SUMIFS(借出!H:H,借出!D:D,C24)-SUMIFS(每日用粉紀錄表!G:G,每日用粉紀錄表!C:C,C24)+SUMIFS(歸還!H:H,歸還!D:D,C24)+SUMIFS(每日用粉紀錄表!I:I,每日用粉紀錄表!C:C,C24) -> 20 | G24: =SUMIFS(期初庫存!G:G,期初庫存!C:C,C24)+SUMIFS(採購入庫!G:G,採購入庫!D:D,C24)-SUMIFS(每日用粉紀錄表!F:F,每日用粉紀錄表!C:C,C24)-SUMIFS(借出!G:G,借出!D:D,C24)+SUMIFS(歸還!G:G,歸還!D:D,C24) -> 3 | H24: 1 | I24: =IF(H24>G24,"採購","否") -> 否 | J24: =IFERROR($G24*25+$F24,"-") -> 95
B25: =MAX($B$3:B24)+1 -> 22 | C25: =IF(烤漆色號編碼!A23="","-",烤漆色號編碼!A23) -> 780-9Q70 | D25: =IF(烤漆色號編碼!C23="","-",烤漆色號編碼!C23) -> 銀灰 | E25: =IF(烤漆色號編碼!B23="","-",烤漆色號編碼!B23) -> ATG | F25: =SUMIFS(期初庫存!F:F,期初庫存!C:C,C25)+SUMIFS(採購入庫!H:H,採購入庫!D:D,C25)-SUMIFS(借出!H:H,借出!D:D,C25)-SUMIFS(每日用粉紀錄表!G:G,每日用粉紀錄表!C:C,C25)+SUMIFS(歸還!H:H,歸還!D:D,C25)+SUMIFS(每日用粉紀錄表!I:I,每日用粉紀錄表!C:C,C25) -> 0 | G25: =SUMIFS(期初庫存!G:G,期初庫存!C:C,C25)+SUMIFS(採購入庫!G:G,採購入庫!D:D,C25)-SUMIFS(每日用粉紀錄表!F:F,每日用粉紀錄表!C:C,C25)-SUMIFS(借出!G:G,借出!D:D,C25)+SUMIFS(歸還!G:G,歸還!D:D,C25) -> 0 | I25: =IF(H25>G25,"採購","否") -> 否 | J25: =IFERROR($G25*25+$F25,"-") -> 0
B26: =MAX($B$3:B25)+1 -> 23 | C26: =IF(烤漆色號編碼!A24="","-",烤漆色號編碼!A24) -> 780-6902 | D26: =IF(烤漆色號編碼!C24="","-",烤漆色號編碼!C24) -> 綠色 | E26: =IF(烤漆色號編碼!B24="","-",烤漆色號編碼!B24) -> GN | F26: =SUMIFS(期初庫存!F:F,期初庫存!C:C,C26)+SUMIFS(採購入庫!H:H,採購入庫!D:D,C26)-SUMIFS(借出!H:H,借出!D:D,C26)-SUMIFS(每日用粉紀錄表!G:G,每日用粉紀錄表!C:C,C26)+SUMIFS(歸還!H:H,歸還!D:D,C26)+SUMIFS(每日用粉紀錄表!I:I,每日用粉紀錄表!C:C,C26) -> 12 | G26: =SUMIFS(期初庫存!G:G,期初庫存!C:C,C26)+SUMIFS(採購入庫!G:G,採購入庫!D:D,C26)-SUMIFS(每日用粉紀錄表!F:F,每日用粉紀錄表!C:C,C26)-SUMIFS(借出!G:G,借出!D:D,C26)+SUMIFS(歸還!G:G,歸還!D:D,C26) -> 2 | H26: 1 | I26: =IF(H26>G26,"採購","否") -> 否 | J26: =IFERROR($G26*25+$F26,"-") -> 62
B27: =MAX($B$3:B26)+1 -> 24 | C27: =IF(烤漆色號編碼!A25="","-",烤漆色號編碼!A25) -> A-10067 | D27: =IF(烤漆色號編碼!C25="","-",烤漆色號編碼!C25) -> 橘色 | E27: =IF(烤漆色號編碼!B25="","-",烤漆色號編碼!B25) -> OE | F27: =SUMIFS(期初庫存!F:F,期初庫存!C:C,C27)+SUMIFS(採購入庫!H:H,採購入庫!D:D,C27)-SUMIFS(借出!H:H,借出!D:D,C27)-SUMIFS(每日用粉紀錄表!G:G,每日用粉紀錄表!C:C,C27)+SUMIFS(歸還!H:H,歸還!D:D,C27)+SUMIFS(每日用粉紀錄表!I:I,每日用粉紀錄表!C:C,C27) -> 71 | G27: =SUMIFS(期初庫存!G:G,期初庫存!C:C,C27)+SUMIFS(採購入庫!G:G,採購入庫!D:D,C27)-SUMIFS(每日用粉紀錄表!F:F,每日用粉紀錄表!C:C,C27)-SUMIFS(借出!G:G,借出!D:D,C27)+SUMIFS(歸還!G:G,歸還!D:D,C27) -> 1 | H27: 1 | I27: =IF(H27>G27,"採購","否") -> 否 | J27: =IFERROR($G27*25+$F27,"-") -> 96
B28: =MAX($B$3:B27)+1 -> 25 | C28: =IF(烤漆色號編碼!A26="","-",烤漆色號編碼!A26) -> 4605-702A | D28: =IF(烤漆色號編碼!C26="","-",烤漆色號編碼!C26) -> 鐵灰 | E28: =IF(烤漆色號編碼!B26="","-",烤漆色號編碼!B26) -> IG | F28: =SUMIFS(期初庫存!F:F,期初庫存!C:C,C28)+SUMIFS(採購入庫!H:H,採購入庫!D:D,C28)-SUMIFS(借出!H:H,借出!D:D,C28)-SUMIFS(每日用粉紀錄表!G:G,每日用粉紀錄表!C:C,C28)+SUMIFS(歸還!H:H,歸還!D:D,C28)+SUMIFS(每日用粉紀錄表!I:I,每日用粉紀錄表!C:C,C28) -> 12 | G28: =SUMIFS(期初庫存!G:G,期初庫存!C:C,C28)+SUMIFS(採購入庫!G:G,採購入庫!D:D,C28)-SUMIFS(每日用粉紀錄表!F:F,每日用粉紀錄表!C:C,C28)-SUMIFS(借出!G:G,借出!D:D,C28)+SUMIFS(歸還!G:G,歸還!D:D,C28) -> 0 | H28: 1 | I28: =IF(H28>G28,"採購","否") -> 採購 | J28: =IFERROR($G28*25+$F28,"-") -> 12
B29: =MAX($B$3:B28)+1 -> 26 | C29: =IF(烤漆色號編碼!A27="","-",烤漆色號編碼!A27) -> 4900-246 | D29: =IF(烤漆色號編碼!C27="","-",烤漆色號編碼!C27) -> 鵝黃色 | E29: =IF(烤漆色號編碼!B27="","-",烤漆色號編碼!B27) -> GYW | F29: =SUMIFS(期初庫存!F:F,期初庫存!C:C,C29)+SUMIFS(採購入庫!H:H,採購入庫!D:D,C29)-SUMIFS(借出!H:H,借出!D:D,C29)-SUMIFS(每日用粉紀錄表!G:G,每日用粉紀錄表!C:C,C29)+SUMIFS(歸還!H:H,歸還!D:D,C29)+SUMIFS(每日用粉紀錄表!I:I,每日用粉紀錄表!C:C,C29) -> 22 | G29: =SUMIFS(期初庫存!G:G,期初庫存!C:C,C29)+SUMIFS(採購入庫!G:G,採購入庫!D:D,C29)-SUMIFS(每日用粉紀錄表!F:F,每日用粉紀錄表!C:C,C29)-SUMIFS(借出!G:G,借出!D:D,C29)+SUMIFS(歸還!G:G,歸還!D:D,C29) -> 0 | H29: 1 | I29: =IF(H29>G29,"採購","否") -> 採購 | J29: =IFERROR($G29*25+$F29,"-") -> 22
B30: =MAX($B$3:B29)+1 -> 27 | C30: =IF(烤漆色號編碼!A28="","-",烤漆色號編碼!A28) -> 4900-149 | D30: =IF(烤漆色號編碼!C28="","-",烤漆色號編碼!C28) -> 粉紅色 | E30: =IF(烤漆色號編碼!B28="","-",烤漆色號編碼!B28) -> PK | F30: =SUMIFS(期初庫存!F:F,期初庫存!C:C,C30)+SUMIFS(採購入庫!H:H,採購入庫!D:D,C30)-SUMIFS(借出!H:H,借出!D:D,C30)-SUMIFS(每日用粉紀錄表!G:G,每日用粉紀錄表!C:C,C30)+SUMIFS(歸還!H:H,歸還!D:D,C30)+SUMIFS(每日用粉紀錄表!I:I,每日用粉紀錄表!C:C,C30) -> 4 | G30: =SUMIFS(期初庫存!G:G,期初庫存!C:C,C30)+SUMIFS(採購入庫!G:G,採購入庫!D:D,C30)-SUMIFS(每日用粉紀錄表!F:F,每日用粉紀錄表!C:C,C30)-SUMIFS(借出!G:G,借出!D:D,C30)+SUMIFS(歸還!G:G,歸還!D:D,C30) -> 2 | H30: 1 | I30: =IF(H30>G30,"採購","否") -> 否 | J30: =IFERROR($G30*25+$F30,"-") -> 54
B31: =MAX($B$3:B30)+1 -> 28 | C31: =IF(烤漆色號編碼!A29="","-",烤漆色號編碼!A29) -> K-5510SCB | D31: =IF(烤漆色號編碼!C29="","-",烤漆色號編碼!C29) -> 黃金閃銀 | E31: =IF(烤漆色號編碼!B29="","-",烤漆色號編碼!B29) -> GSAT | F31: =SUMIFS(期初庫存!F:F,期初庫存!C:C,C31)+SUMIFS(採購入庫!H:H,採購入庫!D:D,C31)-SUMIFS(借出!H:H,借出!D:D,C31)-SUMIFS(每日用粉紀錄表!G:G,每日用粉紀錄表!C:C,C31)+SUMIFS(歸還!H:H,歸還!D:D,C31)+SUMIFS(每日用粉紀錄表!I:I,每日用粉紀錄表!C:C,C31) -> 9 | G31: =SUMIFS(期初庫存!G:G,期初庫存!C:C,C31)+SUMIFS(採購入庫!G:G,採購入庫!D:D,C31)-SUMIFS(每日用粉紀錄表!F:F,每日用粉紀錄表!C:C,C31)-SUMIFS(借出!G:G,借出!D:D,C31)+SUMIFS(歸還!G:G,歸還!D:D,C31) -> 0 | H31: 1 | I31: =IF(H31>G31,"採購","否") -> 採購 | J31: =IFERROR($G31*25+$F31,"-") -> 9
B32: =MAX($B$3:B31)+1 -> 29 | C32: =IF(烤漆色號編碼!A30="","-",烤漆色號編碼!A30) -> O-5337H | D32: =IF(烤漆色號編碼!C30="","-",烤漆色號編碼!C30) -> 黃錘紋 | E32: =IF(烤漆色號編碼!B30="","-",烤漆色號編碼!B30) -> YWH | F32: =SUMIFS(期初庫存!F:F,期初庫存!C:C,C32)+SUMIFS(採購入庫!H:H,採購入庫!D:D,C32)-SUMIFS(借出!H:H,借出!D:D,C32)-SUMIFS(每日用粉紀錄表!G:G,每日用粉紀錄表!C:C,C32)+SUMIFS(歸還!H:H,歸還!D:D,C32)+SUMIFS(每日用粉紀錄表!I:I,每日用粉紀錄表!C:C,C32) -> 0 | G32: =SUMIFS(期初庫存!G:G,期初庫存!C:C,C32)+SUMIFS(採購入庫!G:G,採購入庫!D:D,C32)-SUMIFS(每日用粉紀錄表!F:F,每日用粉紀錄表!C:C,C32)-SUMIFS(借出!G:G,借出!D:D,C32)+SUMIFS(歸還!G:G,歸還!D:D,C32) -> 0 | H32: 1 | I32: =IF(H32>G32,"採購","否") -> 採購 | J32: =IFERROR($G32*25+$F32,"-") -> 0
B33: =MAX($B$3:B32)+1 -> 30 | C33: =IF(烤漆色號編碼!A31="","-",烤漆色號編碼!A31) -> E-BY112 | D33: =IF(烤漆色號編碼!C31="","-",烤漆色號編碼!C31) -> 灰色 | E33: =IF(烤漆色號編碼!B31="","-",烤漆色號編碼!B31) -> ATG | F33: =SUMIFS(期初庫存!F:F,期初庫存!C:C,C33)+SUMIFS(採購入庫!H:H,採購入庫!D:D,C33)-SUMIFS(借出!H:H,借出!D:D,C33)-SUMIFS(每日用粉紀錄表!G:G,每日用粉紀錄表!C:C,C33)+SUMIFS(歸還!H:H,歸還!D:D,C33)+SUMIFS(每日用粉紀錄表!I:I,每日用粉紀錄表!C:C,C33) -> 0 | G33: =SUMIFS(期初庫存!G:G,期初庫存!C:C,C33)+SUMIFS(採購入庫!G:G,採購入庫!D:D,C33)-SUMIFS(每日用粉紀錄表!F:F,每日用粉紀錄表!C:C,C33)-SUMIFS(借出!G:G,借出!D:D,C33)+SUMIFS(歸還!G:G,歸還!D:D,C33) -> 0 | H33: 1 | I33: =IF(H33>G33,"採購","否") -> 採購 | J33: =IFERROR($G33*25+$F33,"-") -> 0
B34: =MAX($B$3:B33)+1 -> 31 | C34: =IF(烤漆色號編碼!A32="","-",烤漆色號編碼!A32) -> BP-133S | D34: =IF(烤漆色號編碼!C32="","-",烤漆色號編碼!C32) -> 閃銀 | E34: =IF(烤漆色號編碼!B32="","-",烤漆色號編碼!B32) -> SAT2 | F34: =SUMIFS(期初庫存!F:F,期初庫存!C:C,C34)+SUMIFS(採購入庫!H:H,採購入庫!D:D,C34)-SUMIFS(借出!H:H,借出!D:D,C34)-SUMIFS(每日用粉紀錄表!G:G,每日用粉紀錄表!C:C,C34)+SUMIFS(歸還!H:H,歸還!D:D,C34)+SUMIFS(每日用粉紀錄表!I:I,每日用粉紀錄表!C:C,C34) -> 9 | G34: =SUMIFS(期初庫存!G:G,期初庫存!C:C,C34)+SUMIFS(採購入庫!G:G,採購入庫!D:D,C34)-SUMIFS(每日用粉紀錄表!F:F,每日用粉紀錄表!C:C,C34)-SUMIFS(借出!G:G,借出!D:D,C34)+SUMIFS(歸還!G:G,歸還!D:D,C34) -> 4 | H34: 1 | I34: =IF(H34>G34,"採購","否") -> 否 | J34: =IFERROR($G34*20+$F34,"-") -> 89
B35: =MAX($B$3:B34)+1 -> 32 | C35: =IF(烤漆色號編碼!A33="","-",烤漆色號編碼!A33) -> PC-20537Y | D35: =IF(烤漆色號編碼!C33="","-",烤漆色號編碼!C33) -> 灰平光 | E35: =IF(烤漆色號編碼!B33="","-",烤漆色號編碼!B33) -> ATG | F35: =SUMIFS(期初庫存!F:F,期初庫存!C:C,C35)+SUMIFS(採購入庫!H:H,採購入庫!D:D,C35)-SUMIFS(借出!H:H,借出!D:D,C35)-SUMIFS(每日用粉紀錄表!G:G,每日用粉紀錄表!C:C,C35)+SUMIFS(歸還!H:H,歸還!D:D,C35)+SUMIFS(每日用粉紀錄表!I:I,每日用粉紀錄表!C:C,C35) -> 6 | G35: =SUMIFS(期初庫存!G:G,期初庫存!C:C,C35)+SUMIFS(採購入庫!G:G,採購入庫!D:D,C35)-SUMIFS(每日用粉紀錄表!F:F,每日用粉紀錄表!C:C,C35)-SUMIFS(借出!G:G,借出!D:D,C35)+SUMIFS(歸還!G:G,歸還!D:D,C35) -> 0 | I35: =IF(H35>G35,"採購","否") -> 否 | J35: =IFERROR($G35*25+$F35,"-") -> 6
B36: =MAX($B$3:B35)+1 -> 33 | C36: =IF(烤漆色號編碼!A34="","-",烤漆色號編碼!A34) -> 008/2H056 | D36: =IF(烤漆色號編碼!C34="","-",烤漆色號編碼!C34) -> 黃亮光 | E36: =IF(烤漆色號編碼!B34="","-",烤漆色號編碼!B34) -> YW1 | F36: =SUMIFS(期初庫存!F:F,期初庫存!C:C,C36)+SUMIFS(採購入庫!H:H,採購入庫!D:D,C36)-SUMIFS(借出!H:H,借出!D:D,C36)-SUMIFS(每日用粉紀錄表!G:G,每日用粉紀錄表!C:C,C36)+SUMIFS(歸還!H:H,歸還!D:D,C36)+SUMIFS(每日用粉紀錄表!I:I,每日用粉紀錄表!C:C,C36) -> 5 | G36: =SUMIFS(期初庫存!G:G,期初庫存!C:C,C36)+SUMIFS(採購入庫!G:G,採購入庫!D:D,C36)-SUMIFS(每日用粉紀錄表!F:F,每日用粉紀錄表!C:C,C36)-SUMIFS(借出!G:G,借出!D:D,C36)+SUMIFS(歸還!G:G,歸還!D:D,C36) -> 12 | H36: 1 | I36: =IF(H36>G36,"採購","否") -> 否 | J36: =IFERROR($G36*25+$F36,"-") -> 305
B37: =MAX($B$3:B36)+1 -> 34 | C37: =IF(烤漆色號編碼!A35="","-",烤漆色號編碼!A35) -> 008/1H174 | D37: =IF(烤漆色號編碼!C35="","-",烤漆色號編碼!C35) -> 白亮光 | E37: =IF(烤漆色號編碼!B35="","-",烤漆色號編碼!B35) -> WE2 | F37: =SUMIFS(期初庫存!F:F,期初庫存!C:C,C37)+SUMIFS(採購入庫!H:H,採購入庫!D:D,C37)-SUMIFS(借出!H:H,借出!D:D,C37)-SUMIFS(每日用粉紀錄表!G:G,每日用粉紀錄表!C:C,C37)+SUMIFS(歸還!H:H,歸還!D:D,C37)+SUMIFS(每日用粉紀錄表!I:I,每日用粉紀錄表!C:C,C37) -> 14 | G37: =SUMIFS(期初庫存!G:G,期初庫存!C:C,C37)+SUMIFS(採購入庫!G:G,採購入庫!D:D,C37)-SUMIFS(每日用粉紀錄表!F:F,每日用粉紀錄表!C:C,C37)-SUMIFS(借出!G:G,借出!D:D,C37)+SUMIFS(歸還!G:G,歸還!D:D,C37) -> 26 | H37: 6 | I37: =IF(H37>G37,"採購","否") -> 否 | J37: =IFERROR($G37*25+$F37,"-") -> 664
B38: =MAX($B$3:B37)+1 -> 35 | C38: =IF(烤漆色號編碼!A36="","-",烤漆色號編碼!A36) -> O-58057 | D38: =IF(烤漆色號編碼!C36="","-",烤漆色號編碼!C36) -> 橘色 | E38: =IF(烤漆色號編碼!B36="","-",烤漆色號編碼!B36) -> OE1 | F38: =SUMIFS(期初庫存!F:F,期初庫存!C:C,C38)+SUMIFS(採購入庫!H:H,採購入庫!D:D,C38)-SUMIFS(借出!H:H,借出!D:D,C38)-SUMIFS(每日用粉紀錄表!G:G,每日用粉紀錄表!C:C,C38)+SUMIFS(歸還!H:H,歸還!D:D,C38)+SUMIFS(每日用粉紀錄表!I:I,每日用粉紀錄表!C:C,C38) -> 12 | G38: =SUMIFS(期初庫存!G:G,期初庫存!C:C,C38)+SUMIFS(採購入庫!G:G,採購入庫!D:D,C38)-SUMIFS(每日用粉紀錄表!F:F,每日用粉紀錄表!C:C,C38)-SUMIFS(借出!G:G,借出!D:D,C38)+SUMIFS(歸還!G:G,歸還!D:D,C38) -> 0 | I38: =IF(H38>G38,"採購","否") -> 否 | J38: =IFERROR($G38*25+$F38,"-") -> 12
B39: =MAX($B$3:B38)+1 -> 36 | C39: =IF(烤漆色號編碼!A37="","-",烤漆色號編碼!A37) -> K-7618 | D39: =IF(烤漆色號編碼!C37="","-",烤漆色號編碼!C37) -> 青綠色 | E39: =IF(烤漆色號編碼!B37="","-",烤漆色號編碼!B37) -> FGN | F39: =SUMIFS(期初庫存!F:F,期初庫存!C:C,C39)+SUMIFS(採購入庫!H:H,採購入庫!D:D,C39)-SUMIFS(借出!H:H,借出!D:D,C39)-SUMIFS(每日用粉紀錄表!G:G,每日用粉紀錄表!C:C,C39)+SUMIFS(歸還!H:H,歸還!D:D,C39)+SUMIFS(每日用粉紀錄表!I:I,每日用粉紀錄表!C:C,C39) -> 19 | G39: =SUMIFS(期初庫存!G:G,期初庫存!C:C,C39)+SUMIFS(採購入庫!G:G,採購入庫!D:D,C39)-SUMIFS(每日用粉紀錄表!F:F,每日用粉紀錄表!C:C,C39)-SUMIFS(借出!G:G,借出!D:D,C39)+SUMIFS(歸還!G:G,歸還!D:D,C39) -> 4 | H39: 1 | I39: =IF(H39>G39,"採購","否") -> 否 | J39: =IFERROR($G39*25+$F39,"-") -> 119
B40: =MAX($B$3:B39)+1 -> 37 | C40: =IF(烤漆色號編碼!A38="","-",烤漆色號編碼!A38) -> 008/35624 | D40: =IF(烤漆色號編碼!C38="","-",烤漆色號編碼!C38) -> 橘色 | E40: =IF(烤漆色號編碼!B38="","-",烤漆色號編碼!B38) -> OE2 | F40: =SUMIFS(期初庫存!F:F,期初庫存!C:C,C40)+SUMIFS(採購入庫!H:H,採購入庫!D:D,C40)-SUMIFS(借出!H:H,借出!D:D,C40)-SUMIFS(每日用粉紀錄表!G:G,每日用粉紀錄表!C:C,C40)+SUMIFS(歸還!H:H,歸還!D:D,C40)+SUMIFS(每日用粉紀錄表!I:I,每日用粉紀錄表!C:C,C40) -> 20 | G40: =SUMIFS(期初庫存!G:G,期初庫存!C:C,C40)+SUMIFS(採購入庫!G:G,採購入庫!D:D,C40)-SUMIFS(每日用粉紀錄表!F:F,每日用粉紀錄表!C:C,C40)-SUMIFS(借出!G:G,借出!D:D,C40)+SUMIFS(歸還!G:G,歸還!D:D,C40) -> 0 | H40: 1 | I40: =IF(H40>G40,"採購","否") -> 採購 | J40: =IFERROR($G40*25+$F40,"-") -> 20
B41: =MAX($B$3:B40)+1 -> 38 | C41: =IF(烤漆色號編碼!A39="","-",烤漆色號編碼!A39) -> 780-7847AT | D41: =IF(烤漆色號編碼!C39="","-",烤漆色號編碼!C39) -> 深藍 | E41: =IF(烤漆色號編碼!B39="","-",烤漆色號編碼!B39) -> DBE | F41: =SUMIFS(期初庫存!F:F,期初庫存!C:C,C41)+SUMIFS(採購入庫!H:H,採購入庫!D:D,C41)-SUMIFS(借出!H:H,借出!D:D,C41)-SUMIFS(每日用粉紀錄表!G:G,每日用粉紀錄表!C:C,C41)+SUMIFS(歸還!H:H,歸還!D:D,C41)+SUMIFS(每日用粉紀錄表!I:I,每日用粉紀錄表!C:C,C41) -> 0 | G41: =SUMIFS(期初庫存!G:G,期初庫存!C:C,C41)+SUMIFS(採購入庫!G:G,採購入庫!D:D,C41)-SUMIFS(每日用粉紀錄表!F:F,每日用粉紀錄表!C:C,C41)-SUMIFS(借出!G:G,借出!D:D,C41)+SUMIFS(歸還!G:G,歸還!D:D,C41) -> 0 | I41: =IF(H41>G41,"採購","否") -> 否 | J41: =IFERROR($G41*25+$F41,"-") -> 0
...

Sheet 對照表
B2: NO: | C2: 粉號 | D2: 當前庫存 | E2: 欄1 | F2: 欄2 | G2: 箱數 | H2: 散粉 | I2: 本期盤存 | J2: 誤差類別 | K2: 誤差值 | L2: 重盤
B3: 1 | C3: =IF(烤漆色號編碼!A2="","-",烤漆色號編碼!A2) -> DP-11485 | D3: =IFERROR(VLOOKUP($C3,當前庫存!$C:$I,5,FALSE),"-") -> 1 | E3: =IFERROR(VLOOKUP($C3,當前庫存!$C:$I,4,FALSE),"-") -> 38 | F3: =IFERROR(VLOOKUP($C3,烤漆色號編碼!$A:$D,4,FALSE)*表格3[[#This Row],[當前庫存]]+表格3[[#This Row],[欄1]],"-") -> 63 | G3: 1 | H3: =5+23+10 -> 38 | I3: =IFERROR(VLOOKUP($C3,烤漆色號編碼!$A:$D,4,FALSE)*表格3[[#This Row],[箱數]]+表格3[[#This Row],[散粉]],"-") -> 63 | J3: =IF(I3>表格3[[#This Row],[欄2]],"多粉",IF(I3<表格3[[#This Row],[欄2]],"少粉","正確")) -> 正確 | K3: =I3-表格3[[#This Row],[欄2]] -> 0
B4: 2 | C4: =IF(烤漆色號編碼!A3="","-",烤漆色號編碼!A3) -> DP-1856 | D4: =IFERROR(VLOOKUP($C4,當前庫存!$C:$I,5,FALSE),"-") -> 1 | E4: =IFERROR(VLOOKUP($C4,當前庫存!$C:$I,4,FALSE),"-") -> 12 | F4: =IFERROR(VLOOKUP($C4,烤漆色號編碼!$A:$D,4,FALSE)*表格3[[#This Row],[當前庫存]]+表格3[[#This Row],[欄1]],"-") -> 37 | G4: 1 | H4: 12 | I4: =IFERROR(VLOOKUP($C4,烤漆色號編碼!$A:$D,4,FALSE)*表格3[[#This Row],[箱數]]+表格3[[#This Row],[散粉]],"-") -> 37 | J4: =IF(I4>表格3[[#This Row],[欄2]],"多粉",IF(I4<表格3[[#This Row],[欄2]],"少粉","正確")) -> 正確 | K4: =I4-表格3[[#This Row],[欄2]] -> 0
B5: 3 | C5: =IF(烤漆色號編碼!A4="","-",烤漆色號編碼!A4) -> O-5905 | D5: =IFERROR(VLOOKUP($C5,當前庫存!$C:$I,5,FALSE),"-") -> 0 | E5: =IFERROR(VLOOKUP($C5,當前庫存!$C:$I,4,FALSE),"-") -> 0 | F5: =IFERROR(VLOOKUP($C5,烤漆色號編碼!$A:$D,4,FALSE)*表格3[[#This Row],[當前庫存]]+表格3[[#This Row],[欄1]],"-") -> 0 | G5: 0 | H5: 0 | I5: =IFERROR(VLOOKUP($C5,烤漆色號編碼!$A:$D,4,FALSE)*表格3[[#This Row],[箱數]]+表格3[[#This Row],[散粉]],"-") -> 0 | J5: =IF(I5>表格3[[#This Row],[欄2]],"多粉",IF(I5<表格3[[#This Row],[欄2]],"少粉","正確")) -> 正確 | K5: =I5-表格3[[#This Row],[欄2]] -> 0
B6: 4 | C6: =IF(烤漆色號編碼!A5="","-",烤漆色號編碼!A5) -> New O-5905 | D6: =IFERROR(VLOOKUP($C6,當前庫存!$C:$I,5,FALSE),"-") -> 2 | E6: =IFERROR(VLOOKUP($C6,當前庫存!$C:$I,4,FALSE),"-") -> 7 | F6: =IFERROR(VLOOKUP($C6,烤漆色號編碼!$A:$D,4,FALSE)*表格3[[#This Row],[當前庫存]]+表格3[[#This Row],[欄1]],"-") -> 57 | G6: 2 | H6: 7 | I6: =IFERROR(VLOOKUP($C6,烤漆色號編碼!$A:$D,4,FALSE)*表格3[[#This Row],[箱數]]+表格3[[#This Row],[散粉]],"-") -> 57 | J6: =IF(I6>表格3[[#This Row],[欄2]],"多粉",IF(I6<表格3[[#This Row],[欄2]],"少粉","正確")) -> 正確 | K6: =I6-表格3[[#This Row],[欄2]] -> 0
B7: 5 | C7: =IF(烤漆色號編碼!A6="","-",烤漆色號編碼!A6) -> 790-41540H | D7: =IFERROR(VLOOKUP($C7,當前庫存!$C:$I,5,FALSE),"-") -> 0 | E7: =IFERROR(VLOOKUP($C7,當前庫存!$C:$I,4,FALSE),"-") -> 27 | F7: =IFERROR(VLOOKUP($C7,烤漆色號編碼!$A:$D,4,FALSE)*表格3[[#This Row],[當前庫存]]+表格3[[#This Row],[欄1]],"-") -> 27 | G7: 0 | H7: =21+6 -> 27 | I7: =IFERROR(VLOOKUP($C7,烤漆色號編碼!$A:$D,4,FALSE)*表格3[[#This Row],[箱數]]+表格3[[#This Row],[散粉]],"-") -> 27 | J7: =IF(I7>表格3[[#This Row],[欄2]],"多粉",IF(I7<表格3[[#This Row],[欄2]],"少粉","正確")) -> 正確 | K7: =I7-表格3[[#This Row],[欄2]] -> 0
B8: 6 | C8: =IF(烤漆色號編碼!A7="","-",烤漆色號編碼!A7) -> 780-310AT | D8: =IFERROR(VLOOKUP($C8,當前庫存!$C:$I,5,FALSE),"-") -> 3 | E8: =IFERROR(VLOOKUP($C8,當前庫存!$C:$I,4,FALSE),"-") -> 12 | F8: =IFERROR(VLOOKUP($C8,烤漆色號編碼!$A:$D,4,FALSE)*表格3[[#This Row],[當前庫存]]+表格3[[#This Row],[欄1]],"-") -> 87 | G8: 3 | H8: 12 | I8: =IFERROR(VLOOKUP($C8,烤漆色號編碼!$A:$D,4,FALSE)*表格3[[#This Row],[箱數]]+表格3[[#This Row],[散粉]],"-") -> 87 | J8: =IF(I8>表格3[[#This Row],[欄2]],"多粉",IF(I8<表格3[[#This Row],[欄2]],"少粉","正確")) -> 正確 | K8: =I8-表格3[[#This Row],[欄2]] -> 0
B9: 7 | C9: =IF(烤漆色號編碼!A8="","-",烤漆色號編碼!A8) -> LT-90442 | D9: =IFERROR(VLOOKUP($C9,當前庫存!$C:$I,5,FALSE),"-") -> 2 | E9: =IFERROR(VLOOKUP($C9,當前庫存!$C:$I,4,FALSE),"-") -> 3 | F9: =IFERROR(VLOOKUP($C9,烤漆色號編碼!$A:$D,4,FALSE)*表格3[[#This Row],[當前庫存]]+表格3[[#This Row],[欄1]],"-") -> 53 | G9: 2 | H9: 3 | I9: =IFERROR(VLOOKUP($C9,烤漆色號編碼!$A:$D,4,FALSE)*表格3[[#This Row],[箱數]]+表格3[[#This Row],[散粉]],"-") -> 53 | J9: =IF(I9>表格3[[#This Row],[欄2]],"多粉",IF(I9<表格3[[#This Row],[欄2]],"少粉","正確")) -> 正確 | K9: =I9-表格3[[#This Row],[欄2]] -> 0
